Workbook

Sheet 印刷・FAX　発注書
B6: 発 注 日 : | C6: 月 日 ( ） | I6: FAX ⇒ 022-355-9775
B7: 納 品 日 : | C7: 月 日 ( ） | I7: 連絡先 ⇒ 080-5704-5653 担当：我妻
B9: ファミリーマート | G9: 店 様 | I9: 有効期限: | L9: 45718 | N9: 45724
B10: ※ 店名のご記入をお願い致します。
B12: 品名 | C12: 産地 | D12: 規格 | E12: 規格 | F12: 保存 | G12: 賞味期限日数目安 | H12: 想定税込売価 | I12: 想定税込 仕入額 | L12: 粗利益率 | M12: 最小発注ロット | N12: 発注数 | O12: 計算表
A13: 1 | B13: バナナ | D13: 太め | E13: １本 | F13: 常温 | G13: 3 | H13: 98 | I13: =ROUNDUP(H13*K13,0) -> 71 | J13: 1 | K13: =J13-L13 -> 0.72 | L13: 0.28 | M13: 4
A14: 2 | B14: バナナ | E14: パック | G14: 3 | H14: 216 | I14: =ROUNDUP(H14*K14,0) -> 156 | J14: 1 | K14: =J14-L14 -> 0.72 | L14: 0.28 | M14: 5
A15: 4 | B15: 新玉ねぎ | D15: M | E15: 2個 | H15: 158 | I15: =ROUNDUP(H15*K15,0) -> 114 | J15: 1 | K15: =J15-L15 -> 0.72 | L15: 0.28 | M15: 5
A16: 5 | B16: 人参（冷蔵保存） | D16: S~L | G16: 5 | H16: 128 | I16: =ROUNDUP(H16*K16,0) -> 93 | J16: 1 | K16: =J16-L16 -> 0.72 | L16: 0.28 | M16: 5
A17: 6 | F17: 要冷 | G17: 7 | H17: 0 | I17: 0 | J17: 1 | K17: =J17-L17 -> 0.72 | L17: 0.28 | M17: 5
A18: 7 | B18: じゃが芋 | D18: M | E18: 3個 | F18: 常温 | G18: 10 | H18: 128 | I18: =ROUNDUP(H18*K18,0) -> 93 | J18: 1 | K18: =J18-L18 -> 0.72 | L18: 0.28 | M18: 3
A19: 8 | B19: 胡瓜 | E19: パック | G19: 5 | H19: 138 | I19: =ROUNDUP(H19*K19,0) -> 100 | J19: 1 | K19: =J19-L19 -> 0.72 | L19: 0.28 | M19: 3
A20: 9 | B20: トマト | E20: ２個 | H20: 238 | I20: 215 | J20: 2 | K20: =J20-L20 -> 1.72 | L20: 0.28 | M20: 3
A21: 10 | B21: レタス | D21: パック | G21: 7 | H21: 258 | I21: =ROUNDUP(H21*K21,0) -> 186 | J21: 1 | K21: =J21-L21 -> 0.72 | L21: 0.28 | M21: 3
A22: 11 | B22: ミニトマト | D22: パック | G22: 5 | H22: 378 | I22: 287 | L22: 0.28 | M22: 3
A23: 12 | B23: ネギ(１本） | E23: 本 | F23: 要冷 | G23: 7 | H23: 108 | I23: =ROUNDUP(H23*K23,0) -> 78 | J23: 1 | K23: =J23-L23 -> 0.72 | L23: 0.28 | M23: 3
A24: 13 | B24: ピーマン | E24: パック | G24: 5 | H24: 198 | I24: =ROUNDUP(H24*K24,0) -> 143 | J24: 1 | K24: =J24-L24 -> 0.72 | L24: 0.28 | M24: 3
A25: 14 | B25: キャベツ | E25: 1/2カット | F25: 要冷 | G25: 5 | H25: 138 | I25: =ROUNDUP(H25*K25,0) -> 100 | J25: 1 | K25: =J25-L25 -> 0.72 | L25: 0.28 | M25: 2
A26: 15 | B26: キャベツ | E26: 1個 | F26: 要冷 | G26: 4 | H26: 358 | I26: =ROUNDUP(H26*K26,0) -> 258 | J26: 1 | K26: =J26-L26 -> 0.72 | L26: 0.28 | M26: 3
A27: 16 | B27: 白菜1/2 | F27: 要冷 | G27: 3 | H27: 108 | I27: =ROUNDUP(H27*K27,0) -> 78 | J27: 1 | K27: =J27-L27 -> 0.72 | L27: 0.28 | M27: 2
A28: 17 | B28: 小松菜 | E28: 袋 | F28: 要冷 | G28: 5 | H28: 168 | I28: =ROUNDUP(H28*K28,0) -> 121 | J28: 1 | K28: =J28-L28 -> 0.72 | L28: 0.28 | M28: 3
A29: 18 | B29: 大根1/2 | E29: 本 | F29: 要冷 | G29: 5 | H29: 148 | I29: =ROUNDUP(H29*K29,0) -> 107 | J29: 1 | K29: =J29-L29 -> 0.72 | L29: 0.28 | M29: 3
A30: 19 | B30: ほうれん草 | C30: 宮城 | E30: 袋 | F30: 要冷 | G30: 5 | H30: 238 | I30: =ROUNDUP(H30*K30,0) -> 172 | J30: 1 | K30: =J30-L30 -> 0.72 | L30: 0.28 | M30: 2
A31: 20 | B31: 茄子 | D31: 3本 | E31: パック | G31: 5 | H31: 178 | I31: =ROUNDUP(H31*K31,0) -> 129 | J31: 1 | K31: =J31-L31 -> 0.72 | L31: 0.28 | M31: 3
A32: 21 | B32: 国産生姜 | E32: パック | F32: 要冷 | G32: 7 | H32: 248 | I32: =ROUNDUP(H32*K32,0) -> 179 | J32: 1 | K32: =J32-L32 -> 0.72 | L32: 0.28 | M32: 3
A33: 22 | B33: アボカド | E33: 個 | F33: 両方 | G33: 5 | H33: 168 | I33: =ROUNDUP(H33*K33,0) -> 121 | J33: 1 | K33: =J33-L33 -> 0.72 | L33: 0.28 | M33: 3
A34: 23 | B34: さつま芋 | E34: パック | F34: 常温 | G34: 10 | H34: 258 | I34: =ROUNDUP(H34*K34,0) -> 186 | J34: 1 | K34: =J34-L34 -> 0.72 | L34: 0.28 | M34: 3
A35: 24 | B35: ごぼう | G35: 10 | H35: 198 | I35: =ROUNDUP(H35*K35,0) -> 143 | J35: 1 | K35: =J35-L35 -> 0.72 | L35: 0.28 | M35: 2
A36: 25 | F36: 要冷 | G36: 5 | I36: =ROUNDUP(H36*K36,0) -> 0 | J36: 1 | K36: =J36-L36 -> 0.72 | L36: 0.28 | M36: 3
A37: 26 | B37: えのき茸 | G37: 5 | H37: 178 | I37: =ROUNDUP(H37*K37,0) -> 129 | J37: 1 | K37: =J37-L37 -> 0.72 | L37: 0.28 | M37: 3
A38: 27 | B38: しめじ | G38: 5 | H38: 148 | I38: =ROUNDUP(H38*K38,0) -> 107 | J38: 1 | K38: =J38-L38 -> 0.72 | L38: 0.28 | M38: 3
A39: 28 | B39: しいたけ | G39: 4 | H39: 158 | I39: =ROUNDUP(H39*K39,0) -> 114 | J39: 1 | K39: =J39-L39 -> 0.72 | L39: 0.28 | M39: 3
A40: 29 | B40: まいたけ | G40: 5 | H40: 158 | I40: =ROUNDUP(H40*K40,0) -> 114 | J40: 1 | K40: =J40-L40 -> 0.72 | L40: 0.28 | M40: 2
A41: 30 | B41: エリンギ | G41: 5 | H41: 158 | I41: =ROUNDUP(H41*K41,0) -> 114 | J41: 1 | K41: =J41-L41 -> 0.72 | L41: 0.28 | M41: 2
A42: 31 | B42: なめこ | E42: 100ｇ | F42: 要冷 | G42: 5 | H42: 108 | I42: =ROUNDUP(H42*K42,0) -> 78 | J42: 1 | K42: =J42-L42 -> 0.72 | L42: 0.28 | M42: 3
A43: 32 | B43: 中国産ニンニク | E43: 3個入り | F43: 常温 | G43: 15 | H43: 168 | I43: =ROUNDUP(H43*K43,0) -> 121 | J43: 1 | K43: =J43-L43 -> 0.72 | L43: 0.28 | M43: 3
A44: 33 | B44: レモン | C44: 米国 | F44: 両方 | G44: 15 | H44: 138 | I44: =ROUNDUP(H44*K44,0) -> 100 | J44: 1 | K44: =J44-L44 -> 0.72 | L44: 0.28 | M44: 3
A45: 34 | B45: 甘夏 | D45: 2個 | E45: パック | F45: 要冷 | G45: 5 | H45: 238 | I45: =ROUNDUP(H45*K45,0) -> 172 | J45: 1 | K45: =J45-L45 -> 0.72 | L45: 0.28 | M45: 3
A46: 35 | B46: 大葉しそ | D46: １０枚 | E46: ﾊﾟｯｸ | G46: 4 | H46: 128 | I46: =ROUNDUP(H46*K46,0) -> 93 | J46: 1 | K46: =J46-L46 -> 0.72 | L46: 0.28 | M46: 3
A47: 36 | B47: 温州みかん | D47: 5個 | E47: パック | F47: 要冷 | G47: 5 | H47: 378 | I47: =ROUNDUP(H47*K47,0) -> 273 | J47: 1 | K47: =J47-L47 -> 0.72 | L47: 0.28 | M47: 3
...

Sheet 入力　発注書
B8: ファミリーマート様 | E8: 納品日： | G8: 46224 | AC8: 【集計】
G9: 3
B12: 品名 | C12: 産地 | D12: 規格 | E12: 規格 | F12: 保存 | G12: 賞味期限日数目安 | H12: 想定税込売価 | I12: 想定税込仕入額 | L12: 粗利益率 | M12: 最小発注ロット | N12: 仙台上愛子 | P12: 仙台高野原 | R12: 栗生4丁目 | T12: AA | V12: BB | X12: A | Z12: B | AC12: 数量 | AD12: 金額
A13: 1 | B13: =IF('印刷・FAX 発注書'!B13="","",'印刷・FAX 発注書'!B13) -> バナナ | C13: =IF('印刷・FAX 発注書'!C13="","",'印刷・FAX 発注書'!C13) | D13: =IF('印刷・FAX 発注書'!D13="","",'印刷・FAX 発注書'!D13) -> 太め | E13: =IF('印刷・FAX 発注書'!E13="","",'印刷・FAX 発注書'!E13) -> １本 | F13: =IF('印刷・FAX 発注書'!F13="","",'印刷・FAX 発注書'!F13) -> 常温 | G13: =IF('印刷・FAX 発注書'!G13="","",'印刷・FAX 発注書'!G13) -> 3 | H13: =IF('印刷・FAX 発注書'!H13="","",'印刷・FAX 発注書'!H13) -> 98 | I13: =IFERROR(ROUNDUP(H13*K13,0),"") -> 71 | J13: 1 | K13: =J13-L13 -> 0.72 | L13: ='印刷・FAX 発注書'!L13 -> 0.28 | M13: =IF('印刷・FAX 発注書'!M13="","",'印刷・FAX 発注書'!M13) -> 4 | O13: =IFERROR($M13*N13,0) -> 0 | Q13: =IFERROR($M13*P13,0) -> 0 | S13: =IFERROR($M13*R13,0) -> 0 | U13: =IFERROR($M13*T13,0) -> 0 | W13: =IFERROR($M13*V13,0) -> 0 | Y13: =IFERROR($M13*X13,0) -> 0 | AA13: =IFERROR($M13*Z13,0) -> 0 | AC13: =IFERROR((N13+P13+R13)*M13,"") -> 0 | AD13: =IFERROR(I13*AC13,"") -> 0
A14: 2 | B14: =IF('印刷・FAX 発注書'!B14="","",'印刷・FAX 発注書'!B14) -> バナナ | C14: =IF('印刷・FAX 発注書'!C14="","",'印刷・FAX 発注書'!C14) | D14: =IF('印刷・FAX 発注書'!D14="","",'印刷・FAX 発注書'!D14) | E14: =IF('印刷・FAX 発注書'!E14="","",'印刷・FAX 発注書'!E14) -> パック | F14: =IF('印刷・FAX 発注書'!F14="","",'印刷・FAX 発注書'!F14) | G14: =IF('印刷・FAX 発注書'!G14="","",'印刷・FAX 発注書'!G14) -> 3 | H14: =IF('印刷・FAX 発注書'!H14="","",'印刷・FAX 発注書'!H14) -> 216 | I14: =IFERROR(ROUNDUP(H14*K14,0),"") -> 156 | J14: 1 | K14: =J14-L14 -> 0.72 | L14: ='印刷・FAX 発注書'!L14 -> 0.28 | M14: =IF('印刷・FAX 発注書'!M14="","",'印刷・FAX 発注書'!M14) -> 5 | O14: =IFERROR($M14*N14,0) -> 0 | P14: 1 | Q14: =IFERROR($M14*P14,0) -> 5 | S14: =IFERROR($M14*R14,0) -> 0 | U14: =IFERROR($M14*T14,0) -> 0 | W14: =IFERROR($M14*V14,0) -> 0 | Y14: =IFERROR($M14*X14,0) -> 0 | AA14: =IFERROR($M14*Z14,0) -> 0 | AC14: =IFERROR((N14+P14+R14)*M14,"") -> 5 | AD14: =IFERROR(I14*AC14,"") -> 780
A15: 3 | B15: =IF('印刷・FAX 発注書'!B15="","",'印刷・FAX 発注書'!B15) -> 新玉ねぎ | C15: =IF('印刷・FAX 発注書'!C15="","",'印刷・FAX 発注書'!C15) | D15: =IF('印刷・FAX 発注書'!D15="","",'印刷・FAX 発注書'!D15) -> M | E15: =IF('印刷・FAX 発注書'!E15="","",'印刷・FAX 発注書'!E15) -> 2個 | F15: =IF('印刷・FAX 発注書'!F15="","",'印刷・FAX 発注書'!F15) | G15: =IF('印刷・FAX 発注書'!G15="","",'印刷・FAX 発注書'!G15) | H15: =IF('印刷・FAX 発注書'!H15="","",'印刷・FAX 発注書'!H15) -> 158 | I15: =IFERROR(ROUNDUP(H15*K15,0),"") -> 272 | J15: 2 | K15: =J15-L15 -> 1.72 | L15: ='印刷・FAX 発注書'!L15 -> 0.28 | M15: =IF('印刷・FAX 発注書'!M15="","",'印刷・FAX 発注書'!M15) -> 5 | O15: =IFERROR($M15*N15,0) -> 0 | Q15: =IFERROR($M15*P15,0) -> 0 | S15: =IFERROR($M15*R15,0) -> 0 | U15: =IFERROR($M15*T15,0) -> 0 | W15: =IFERROR($M15*V15,0) -> 0 | Y15: =IFERROR($M15*X15,0) -> 0 | AA15: =IFERROR($M15*Z15,0) -> 0 | AC15: =IFERROR((N15+P15+R15)*M15,"") -> 0 | AD15: =IFERROR(I15*AC15,"") -> 0
A16: 4 | B16: =IF('印刷・FAX 発注書'!B15="","",'印刷・FAX 発注書'!B15) -> 新玉ねぎ | C16: =IF('印刷・FAX 発注書'!C15="","",'印刷・FAX 発注書'!C15) | D16: =IF('印刷・FAX 発注書'!D15="","",'印刷・FAX 発注書'!D15) -> M | E16: =IF('印刷・FAX 発注書'!E15="","",'印刷・FAX 発注書'!E15) -> 2個 | F16: =IF('印刷・FAX 発注書'!F15="","",'印刷・FAX 発注書'!F15) | G16: =IF('印刷・FAX 発注書'!G15="","",'印刷・FAX 発注書'!G15) | H16: =IF('印刷・FAX 発注書'!H15="","",'印刷・FAX 発注書'!H15) -> 158 | I16: =IFERROR(ROUNDUP(H16*K16,0),"") -> 114 | J16: 1 | K16: =J16-L16 -> 0.72 | L16: ='印刷・FAX 発注書'!L15 -> 0.28 | M16: =IF('印刷・FAX 発注書'!M15="","",'印刷・FAX 発注書'!M15) -> 5 | O16: =IFERROR($M16*N16,0) -> 0 | P16: 1 | Q16: =IFERROR($M16*P16,0) -> 5 | S16: =IFERROR($M16*R16,0) -> 0 | U16: =IFERROR($M16*T16,0) -> 0 | W16: =IFERROR($M16*V16,0) -> 0 | Y16: =IFERROR($M16*X16,0) -> 0 | AA16: =IFERROR($M16*Z16,0) -> 0 | AC16: =IFERROR((N16+P16+R16)*M16,"") -> 5 | AD16: =IFERROR(I16*AC16,"") -> 570
A17: 5 | B17: =IF('印刷・FAX 発注書'!B16="","",'印刷・FAX 発注書'!B16) -> 人参（冷蔵保存） | C17: =IF('印刷・FAX 発注書'!C16="","",'印刷・FAX 発注書'!C16) | D17: =IF('印刷・FAX 発注書'!D16="","",'印刷・FAX 発注書'!D16) -> S~L | E17: =IF('印刷・FAX 発注書'!E16="","",'印刷・FAX 発注書'!E16) | F17: =IF('印刷・FAX 発注書'!F16="","",'印刷・FAX 発注書'!F16) | G17: =IF('印刷・FAX 発注書'!G16="","",'印刷・FAX 発注書'!G16) -> 5 | H17: =IF('印刷・FAX 発注書'!H16="","",'印刷・FAX 発注書'!H16) -> 128 | I17: =IFERROR(ROUNDUP(H17*K17,0),"") -> 93 | J17: 1 | K17: =J17-L17 -> 0.72 | L17: ='印刷・FAX 発注書'!L16 -> 0.28 | M17: =IF('印刷・FAX 発注書'!M16="","",'印刷・FAX 発注書'!M16) -> 5 | O17: =IFERROR($M17*N17,0) -> 0 | Q17: =IFERROR($M17*P17,0) -> 0 | S17: =IFERROR($M17*R17,0) -> 0 | U17: =IFERROR($M17*T17,0) -> 0 | W17: =IFERROR($M17*V17,0) -> 0 | Y17: =IFERROR($M17*X17,0) -> 0 | AA17: =IFERROR($M17*Z17,0) -> 0 | AC17: =IFERROR((N17+P17+R17)*M17,"") -> 0 | AD17: =IFERROR(I17*AC17,"") -> 0
A18: 6 | B18: =IF('印刷・FAX 発注書'!B17="","",'印刷・FAX 発注書'!B17) | C18: =IF('印刷・FAX 発注書'!C17="","",'印刷・FAX 発注書'!C17) | D18: =IF('印刷・FAX 発注書'!D17="","",'印刷・FAX 発注書'!D17) | E18: =IF('印刷・FAX 発注書'!E17="","",'印刷・FAX 発注書'!E17) | F18: =IF('印刷・FAX 発注書'!F17="","",'印刷・FAX 発注書'!F17) -> 要冷 | G18: =IF('印刷・FAX 発注書'!G17="","",'印刷・FAX 発注書'!G17) -> 7 | H18: =IF('印刷・FAX 発注書'!H17="","",'印刷・FAX 発注書'!H17) -> 0 | I18: =IFERROR(ROUNDUP(H18*K18,0),"") -> 0 | J18: 1 | K18: =J18-L18 -> 0.72 | L18: ='印刷・FAX 発注書'!L17 -> 0.28 | M18: =IF('印刷・FAX 発注書'!M17="","",'印刷・FAX 発注書'!M17) -> 5 | O18: =IFERROR($M18*N18,0) -> 0 | Q18: =IFERROR($M18*P18,0) -> 0 | S18: =IFERROR($M18*R18,0) -> 0 | U18: =IFERROR($M18*T18,0) -> 0 | W18: =IFERROR($M18*V18,0) -> 0 | Y18: =IFERROR($M18*X18,0) -> 0 | AA18: =IFERROR($M18*Z18,0) -> 0 | AC18: =IFERROR((N18+P18+R18)*M18,"") -> 0 | AD18: =IFERROR(I18*AC18,"") -> 0
A19: 7 | B19: =IF('印刷・FAX 発注書'!B18="","",'印刷・FAX 発注書'!B18) -> じゃが芋 | C19: =IF('印刷・FAX 発注書'!C18="","",'印刷・FAX 発注書'!C18) | D19: =IF('印刷・FAX 発注書'!D18="","",'印刷・FAX 発注書'!D18) -> M | E19: =IF('印刷・FAX 発注書'!E18="","",'印刷・FAX 発注書'!E18) -> 3個 | F19: =IF('印刷・FAX 発注書'!F18="","",'印刷・FAX 発注書'!F18) -> 常温 | G19: =IF('印刷・FAX 発注書'!G18="","",'印刷・FAX 発注書'!G18) -> 10 | H19: =IF('印刷・FAX 発注書'!H18="","",'印刷・FAX 発注書'!H18) -> 128 | I19: =IFERROR(ROUNDUP(H19*K19,0),"") -> 93 | J19: 1 | K19: =J19-L19 -> 0.72 | L19: ='印刷・FAX 発注書'!L18 -> 0.28 | M19: =IF('印刷・FAX 発注書'!M18="","",'印刷・FAX 発注書'!M18) -> 3 | O19: =IFERROR($M19*N19,0) -> 0 | Q19: =IFERROR($M19*P19,0) -> 0 | S19: =IFERROR($M19*R19,0) -> 0 | U19: =IFERROR($M19*T19,0) -> 0 | W19: =IFERROR($M19*V19,0) -> 0 | Y19: =IFERROR($M19*X19,0) -> 0 | AA19: =IFERROR($M19*Z19,0) -> 0 | AC19: =IFERROR((N19+P19+R19)*M19,"") -> 0 | AD19: =IFERROR(I19*AC19,"") -> 0
A20: 8 | B20: =IF('印刷・FAX 発注書'!B19="","",'印刷・FAX 発注書'!B19) -> 胡瓜 | C20: =IF('印刷・FAX 発注書'!C19="","",'印刷・FAX 発注書'!C19) | D20: =IF('印刷・FAX 発注書'!D19="","",'印刷・FAX 発注書'!D19) | E20: =IF('印刷・FAX 発注書'!E19="","",'印刷・FAX 発注書'!E19) -> パック | F20: =IF('印刷・FAX 発注書'!F19="","",'印刷・FAX 発注書'!F19) | G20: =IF('印刷・FAX 発注書'!G19="","",'印刷・FAX 発注書'!G19) -> 5 | H20: =IF('印刷・FAX 発注書'!H19="","",'印刷・FAX 発注書'!H19) -> 138 | I20: =IFERROR(ROUNDUP(H20*K20,0),"") -> 100 | J20: 1 | K20: =J20-L20 -> 0.72 | L20: ='印刷・FAX 発注書'!L19 -> 0.28 | M20: =IF('印刷・FAX 発注書'!M19="","",'印刷・FAX 発注書'!M19) -> 3 | O20: =IFERROR($M20*N20,0) -> 0 | Q20: =IFERROR($M20*P20,0) -> 0 | S20: =IFERROR($M20*R20,0) -> 0 | U20: =IFERROR($M20*T20,0) -> 0 | W20: =IFERROR($M20*V20,0) -> 0 | Y20: =IFERROR($M20*X20,0) -> 0 | AA20: =IFERROR($M20*Z20,0) -> 0 | AC20: =IFERROR((N20+P20+R20)*M20,"") -> 0 | AD20: =IFERROR(I20*AC20,"") -> 0
A21: 9 | B21: =IF('印刷・FAX 発注書'!B20="","",'印刷・FAX 発注書'!B20) -> トマト | C21: =IF('印刷・FAX 発注書'!C20="","",'印刷・FAX 発注書'!C20) | D21: =IF('印刷・FAX 発注書'!D20="","",'印刷・FAX 発注書'!D20) | E21: =IF('印刷・FAX 発注書'!E20="","",'印刷・FAX 発注書'!E20) -> ２個 | F21: =IF('印刷・FAX 発注書'!F20="","",'印刷・FAX 発注書'!F20) | G21: =IF('印刷・FAX 発注書'!G20="","",'印刷・FAX 発注書'!G20) | H21: =IF('印刷・FAX 発注書'!H20="","",'印刷・FAX 発注書'!H20) -> 238 | I21: =IFERROR(ROUNDUP(H21*K21,0),"") -> 172 | J21: 1 | K21: =J21-L21 -> 0.72 | L21: ='印刷・FAX 発注書'!L20 -> 0.28 | M21: =IF('印刷・FAX 発注書'!M20="","",'印刷・FAX 発注書'!M20) -> 3 | O21: =IFERROR($M21*N21,0) -> 0 | Q21: =IFERROR($M21*P21,0) -> 0 | S21: =IFERROR($M21*R21,0) -> 0 | U21: =IFERROR($M21*T21,0) -> 0 | W21: =IFERROR($M21*V21,0) -> 0 | Y21: =IFERROR($M21*X21,0) -> 0 | AA21: =IFERROR($M21*Z21,0) -> 0 | AC21: =IFERROR((N21+P21+R21)*M21,"") -> 0 | AD21: =IFERROR(I21*AC21,"") -> 0
A22: 10 | B22: =IF('印刷・FAX 発注書'!B21="","",'印刷・FAX 発注書'!B21) -> レタス | C22: =IF('印刷・FAX 発注書'!C21="","",'印刷・FAX 発注書'!C21) | D22: =IF('印刷・FAX 発注書'!D21="","",'印刷・FAX 発注書'!D21) -> パック | E22: =IF('印刷・FAX 発注書'!E21="","",'印刷・FAX 発注書'!E21) | F22: =IF('印刷・FAX 発注書'!F21="","",'印刷・FAX 発注書'!F21) | G22: =IF('印刷・FAX 発注書'!G21="","",'印刷・FAX 発注書'!G21) -> 7 | H22: =IF('印刷・FAX 発注書'!H21="","",'印刷・FAX 発注書'!H21) -> 258 | I22: =IFERROR(ROUNDUP(H22*K22,0),"") -> 186 | J22: 1 | K22: =J22-L22 -> 0.72 | L22: ='印刷・FAX 発注書'!L21 -> 0.28 | M22: =IF('印刷・FAX 発注書'!M21="","",'印刷・FAX 発注書'!M21) -> 3 | O22: =IFERROR($M22*N22,0) -> 0 | Q22: =IFERROR($M22*P22,0) -> 0 | S22: =IFERROR($M22*R22,0) -> 0 | U22: =IFERROR($M22*T22,0) -> 0 | W22: =IFERROR($M22*V22,0) -> 0 | Y22: =IFERROR($M22*X22,0) -> 0 | AA22: =IFERROR($M22*Z22,0) -> 0 | AC22: =IFERROR((N22+P22+R22)*M22,"") -> 0 | AD22: =IFERROR(I22*AC22,"") -> 0
A23: 11 | B23: =IF('印刷・FAX 発注書'!B22="","",'印刷・FAX 発注書'!B22) -> ミニトマト | C23: =IF('印刷・FAX 発注書'!C22="","",'印刷・FAX 発注書'!C22) | D23: =IF('印刷・FAX 発注書'!D22="","",'印刷・FAX 発注書'!D22) -> パック | E23: =IF('印刷・FAX 発注書'!E22="","",'印刷・FAX 発注書'!E22) | F23: =IF('印刷・FAX 発注書'!F22="","",'印刷・FAX 発注書'!F22) | G23: =IF('印刷・FAX 発注書'!G22="","",'印刷・FAX 発注書'!G22) -> 5 | H23: =IF('印刷・FAX 発注書'!H22="","",'印刷・FAX 発注書'!H22) -> 378 | I23: =IFERROR(ROUNDUP(H23*K23,0),"") -> 273 | J23: 1 | K23: =J23-L23 -> 0.72 | L23: ='印刷・FAX 発注書'!L22 -> 0.28 | M23: =IF('印刷・FAX 発注書'!M22="","",'印刷・FAX 発注書'!M22) -> 3 | O23: =IFERROR($M23*N23,0) -> 0 | Q23: =IFERROR($M23*P23,0) -> 0 | S23: =IFERROR($M23*R23,0) -> 0 | U23: =IFERROR($M23*T23,0) -> 0 | W23: =IFERROR($M23*V23,0) -> 0 | Y23: =IFERROR($M23*X23,0) -> 0 | AA23: =IFERROR($M23*Z23,0) -> 0 | AC23: =IFERROR((N23+P23+R23)*M23,"") -> 0 | AD23: =IFERROR(I23*AC23,"") -> 0
A24: 12 | B24: =IF('印刷・FAX 発注書'!B23="","",'印刷・FAX 発注書'!B23) -> ネギ(１本） | C24: =IF('印刷・FAX 発注書'!C23="","",'印刷・FAX 発注書'!C23) | D24: =IF('印刷・FAX 発注書'!D23="","",'印刷・FAX 発注書'!D23) | E24: =IF('印刷・FAX 発注書'!E23="","",'印刷・FAX 発注書'!E23) -> 本 | F24: =IF('印刷・FAX 発注書'!F23="","",'印刷・FAX 発注書'!F23) -> 要冷 | G24: =IF('印刷・FAX 発注書'!G23="","",'印刷・FAX 発注書'!G23) -> 7 | H24: =IF('印刷・FAX 発注書'!H23="","",'印刷・FAX 発注書'!H23) -> 108 | I24: =IFERROR(ROUNDUP(H24*K24,0),"") -> 78 | J24: 1 | K24: =J24-L24 -> 0.72 | L24: ='印刷・FAX 発注書'!L23 -> 0.28 | M24: =IF('印刷・FAX 発注書'!M23="","",'印刷・FAX 発注書'!M23) -> 3 | O24: =IFERROR($M24*N24,0) -> 0 | P24: 1 | Q24: =IFERROR($M24*P24,0) -> 3 | S24: =IFERROR($M24*R24,0) -> 0 | U24: =IFERROR($M24*T24,0) -> 0 | W24: =IFERROR($M24*V24,0) -> 0 | Y24: =IFERROR($M24*X24,0) -> 0 | AA24: =IFERROR($M24*Z24,0) -> 0 | AC24: =IFERROR((N24+P24+R24)*M24,"") -> 3 | AD24: =IFERROR(I24*AC24,"") -> 234
A25: 13 | B25: =IF('印刷・FAX 発注書'!B24="","",'印刷・FAX 発注書'!B24) -> ピーマン | C25: =IF('印刷・FAX 発注書'!C24="","",'印刷・FAX 発注書'!C24) | D25: =IF('印刷・FAX 発注書'!D24="","",'印刷・FAX 発注書'!D24) | E25: =IF('印刷・FAX 発注書'!E24="","",'印刷・FAX 発注書'!E24) -> パック | F25: =IF('印刷・FAX 発注書'!F24="","",'印刷・FAX 発注書'!F24) | G25: =IF('印刷・FAX 発注書'!G24="","",'印刷・FAX 発注書'!G24) -> 5 | H25: =IF('印刷・FAX 発注書'!H24="","",'印刷・FAX 発注書'!H24) -> 198 | I25: =IFERROR(ROUNDUP(H25*K25,0),"") -> 143 | J25: 1 | K25: =J25-L25 -> 0.72 | L25: ='印刷・FAX 発注書'!L24 -> 0.28 | M25: =IF('印刷・FAX 発注書'!M24="","",'印刷・FAX 発注書'!M24) -> 3 | O25: =IFERROR($M25*N25,0) -> 0 | Q25: =IFERROR($M25*P25,0) -> 0 | S25: =IFERROR($M25*R25,0) -> 0 | U25: =IFERROR($M25*T25,0) -> 0 | W25: =IFERROR($M25*V25,0) -> 0 | Y25: =IFERROR($M25*X25,0) -> 0 | AA25: =IFERROR($M25*Z25,0) -> 0 | AC25: =IFERROR((N25+P25+R25)*M25,"") -> 0 | AD25: =IFERROR(I25*AC25,"") -> 0
A26: 14 | B26: =IF('印刷・FAX 発注書'!B25="","",'印刷・FAX 発注書'!B25) -> キャベツ | C26: =IF('印刷・FAX 発注書'!C25="","",'印刷・FAX 発注書'!C25) | D26: =IF('印刷・FAX 発注書'!D25="","",'印刷・FAX 発注書'!D25) | E26: =IF('印刷・FAX 発注書'!E25="","",'印刷・FAX 発注書'!E25) -> 1/2カット | F26: =IF('印刷・FAX 発注書'!F25="","",'印刷・FAX 発注書'!F25) -> 要冷 | G26: =IF('印刷・FAX 発注書'!G25="","",'印刷・FAX 発注書'!G25) -> 5 | H26: =IF('印刷・FAX 発注書'!H25="","",'印刷・FAX 発注書'!H25) -> 138 | I26: =IFERROR(ROUNDUP(H26*K26,0),"") -> 100 | J26: 1 | K26: =J26-L26 -> 0.72 | L26: ='印刷・FAX 発注書'!L25 -> 0.28 | M26: =IF('印刷・FAX 発注書'!M25="","",'印刷・FAX 発注書'!M25) -> 2 | O26: =IFERROR($M26*N26,0) -> 0 | P26: 1 | Q26: =IFERROR($M26*P26,0) -> 2 | S26: =IFERROR($M26*R26,0) -> 0 | U26: =IFERROR($M26*T26,0) -> 0 | W26: =IFERROR($M26*V26,0) -> 0 | Y26: =IFERROR($M26*X26,0) -> 0 | AA26: =IFERROR($M26*Z26,0) -> 0 | AC26: =IFERROR((N26+P26+R26)*M26,"") -> 2 | AD26: =IFERROR(I26*AC26,"") -> 200
A27: 15 | B27: =IF('印刷・FAX 発注書'!B26="","",'印刷・FAX 発注書'!B26) -> キャベツ | C27: =IF('印刷・FAX 発注書'!C26="","",'印刷・FAX 発注書'!C26) | D27: =IF('印刷・FAX 発注書'!D26="","",'印刷・FAX 発注書'!D26) | E27: =IF('印刷・FAX 発注書'!E26="","",'印刷・FAX 発注書'!E26) -> 1個 | F27: =IF('印刷・FAX 発注書'!F26="","",'印刷・FAX 発注書'!F26) -> 要冷 | G27: =IF('印刷・FAX 発注書'!G26="","",'印刷・FAX 発注書'!G26) -> 4 | H27: =IF('印刷・FAX 発注書'!H26="","",'印刷・FAX 発注書'!H26) -> 358 | I27: =IFERROR(ROUNDUP(H27*K27,0),"") -> 258 | J27: 1 | K27: =J27-L27 -> 0.72 | L27: ='印刷・FAX 発注書'!L26 -> 0.28 | M27: =IF('印刷・FAX 発注書'!M26="","",'印刷・FAX 発注書'!M26) -> 3 | O27: =IFERROR($M27*N27,0) -> 0 | Q27: =IFERROR($M27*P27,0) -> 0 | S27: =IFERROR($M27*R27,0) -> 0 | U27: =IFERROR($M27*T27,0) -> 0 | W27: =IFERROR($M27*V27,0) -> 0 | Y27: =IFERROR($M27*X27,0) -> 0 | AA27: =IFERROR($M27*Z27,0) -> 0 | AC27: =IFERROR((N27+P27+R27)*M27,"") -> 0 | AD27: =IFERROR(I27*AC27,"") -> 0
A28: 16 | B28: =IF('印刷・FAX 発注書'!B27="","",'印刷・FAX 発注書'!B27) -> 白菜1/2 | C28: =IF('印刷・FAX 発注書'!C27="","",'印刷・FAX 発注書'!C27) | D28: =IF('印刷・FAX 発注書'!D27="","",'印刷・FAX 発注書'!D27) | E28: =IF('印刷・FAX 発注書'!E27="","",'印刷・FAX 発注書'!E27) | F28: =IF('印刷・FAX 発注書'!F27="","",'印刷・FAX 発注書'!F27) -> 要冷 | G28: =IF('印刷・FAX 発注書'!G27="","",'印刷・FAX 発注書'!G27) -> 3 | H28: =IF('印刷・FAX 発注書'!H27="","",'印刷・FAX 発注書'!H27) -> 108 | I28: =IFERROR(ROUNDUP(H28*K28,0),"") -> 78 | J28: 1 | K28: =J28-L28 -> 0.72 | L28: ='印刷・FAX 発注書'!L27 -> 0.28 | M28: =IF('印刷・FAX 発注書'!M27="","",'印刷・FAX 発注書'!M27) -> 2 | O28: =IFERROR($M28*N28,0) -> 0 | Q28: =IFERROR($M28*P28,0) -> 0 | S28: =IFERROR($M28*R28,0) -> 0 | U28: =IFERROR($M28*T28,0) -> 0 | W28: =IFERROR($M28*V28,0) -> 0 | Y28: =IFERROR($M28*X28,0) -> 0 | AA28: =IFERROR($M28*Z28,0) -> 0 | AC28: =IFERROR((N28+P28+R28)*M28,"") -> 0 | AD28: =IFERROR(I28*AC28,"") -> 0
A29: 17 | B29: =IF('印刷・FAX 発注書'!B28="","",'印刷・FAX 発注書'!B28) -> 小松菜 | C29: =IF('印刷・FAX 発注書'!#REF!="","",'印刷・FAX 発注書'!#REF!) -> #REF! | D29: =IF('印刷・FAX 発注書'!#REF!="","",'印刷・FAX 発注書'!#REF!) -> #REF! | E29: =IF('印刷・FAX 発注書'!E28="","",'印刷・FAX 発注書'!E28) -> 袋 | F29: =IF('印刷・FAX 発注書'!F28="","",'印刷・FAX 発注書'!F28) -> 要冷 | G29: =IF('印刷・FAX 発注書'!G28="","",'印刷・FAX 発注書'!G28) -> 5 | H29: =IF('印刷・FAX 発注書'!H28="","",'印刷・FAX 発注書'!H28) -> 168 | I29: =IFERROR(ROUNDUP(H29*K29,0),"") -> 121 | J29: 1 | K29: =J29-L29 -> 0.72 | L29: ='印刷・FAX 発注書'!L28 -> 0.28 | M29: =IF('印刷・FAX 発注書'!M28="","",'印刷・FAX 発注書'!M28) -> 3 | O29: =IFERROR($M29*N29,0) -> 0 | Q29: =IFERROR($M29*P29,0) -> 0 | S29: =IFERROR($M29*R29,0) -> 0 | U29: =IFERROR($M29*T29,0) -> 0 | W29: =IFERROR($M29*V29,0) -> 0 | Y29: =IFERROR($M29*X29,0) -> 0 | AA29: =IFERROR($M29*Z29,0) -> 0 | AC29: =IFERROR((N29+P29+R29)*M29,"") -> 0 | AD29: =IFERROR(I29*AC29,"") -> 0
A30: 18 | B30: =IF('印刷・FAX 発注書'!B29="","",'印刷・FAX 発注書'!B29) -> 大根1/2 | C30: =IF('印刷・FAX 発注書'!C28="","",'印刷・FAX 発注書'!C28) | D30: =IF('印刷・FAX 発注書'!D28="","",'印刷・FAX 発注書'!D28) | E30: =IF('印刷・FAX 発注書'!E29="","",'印刷・FAX 発注書'!E29) -> 本 | F30: =IF('印刷・FAX 発注書'!F29="","",'印刷・FAX 発注書'!F29) -> 要冷 | G30: =IF('印刷・FAX 発注書'!G29="","",'印刷・FAX 発注書'!G29) -> 5 | H30: =IF('印刷・FAX 発注書'!H29="","",'印刷・FAX 発注書'!H29) -> 148 | I30: =IFERROR(ROUNDUP(H30*K30,0),"") -> 107 | J30: 1 | K30: =J30-L30 -> 0.72 | L30: ='印刷・FAX 発注書'!L29 -> 0.28 | M30: =IF('印刷・FAX 発注書'!M29="","",'印刷・FAX 発注書'!M29) -> 3 | O30: =IFERROR($M30*N30,0) -> 0 | Q30: =IFERROR($M30*P30,0) -> 0 | S30: =IFERROR($M30*R30,0) -> 0 | U30: =IFERROR($M30*T30,0) -> 0 | W30: =IFERROR($M30*V30,0) -> 0 | Y30: =IFERROR($M30*X30,0) -> 0 | AA30: =IFERROR($M30*Z30,0) -> 0 | AC30: =IFERROR((N30+P30+R30)*M30,"") -> 0 | AD30: =IFERROR(I30*AC30,"") -> 0
A31: 19 | B31: =IF('印刷・FAX 発注書'!B30="","",'印刷・FAX 発注書'!B30) -> ほうれん草 | C31: =IF('印刷・FAX 発注書'!C29="","",'印刷・FAX 発注書'!C29) | D31: =IF('印刷・FAX 発注書'!D29="","",'印刷・FAX 発注書'!D29) | E31: =IF('印刷・FAX 発注書'!E30="","",'印刷・FAX 発注書'!E30) -> 袋 | F31: =IF('印刷・FAX 発注書'!F30="","",'印刷・FAX 発注書'!F30) -> 要冷 | G31: =IF('印刷・FAX 発注書'!G30="","",'印刷・FAX 発注書'!G30) -> 5 | H31: =IF('印刷・FAX 発注書'!H30="","",'印刷・FAX 発注書'!H30) -> 238 | I31: =IFERROR(ROUNDUP(H31*K31,0),"") -> 172 | J31: 1 | K31: =J31-L31 -> 0.72 | L31: ='印刷・FAX 発注書'!L30 -> 0.28 | M31: =IF('印刷・FAX 発注書'!M30="","",'印刷・FAX 発注書'!M30) -> 2 | O31: =IFERROR($M31*N31,0) -> 0 | Q31: =IFERROR($M31*P31,0) -> 0 | S31: =IFERROR($M31*R31,0) -> 0 | U31: =IFERROR($M31*T31,0) -> 0 | W31: =IFERROR($M31*V31,0) -> 0 | Y31: =IFERROR($M31*X31,0) -> 0 | AA31: =IFERROR($M31*Z31,0) -> 0 | AC31: =IFERROR((N31+P31+R31)*M31,"") -> 0 | AD31: =IFERROR(I31*AC31,"") -> 0
A32: 20 | B32: =IF('印刷・FAX 発注書'!B31="","",'印刷・FAX 発注書'!B31) -> 茄子 | C32: =IF('印刷・FAX 発注書'!C30="","",'印刷・FAX 発注書'!C30) -> 宮城 | D32: =IF('印刷・FAX 発注書'!D30="","",'印刷・FAX 発注書'!D30) | E32: =IF('印刷・FAX 発注書'!E31="","",'印刷・FAX 発注書'!E31) -> パック | F32: =IF('印刷・FAX 発注書'!F31="","",'印刷・FAX 発注書'!F31) | G32: =IF('印刷・FAX 発注書'!G31="","",'印刷・FAX 発注書'!G31) -> 5 | H32: =IF('印刷・FAX 発注書'!H31="","",'印刷・FAX 発注書'!H31) -> 178 | I32: =IFERROR(ROUNDUP(H32*K32,0),"") -> 129 | J32: 1 | K32: =J32-L32 -> 0.72 | L32: ='印刷・FAX 発注書'!L31 -> 0.28 | M32: =IF('印刷・FAX 発注書'!M31="","",'印刷・FAX 発注書'!M31) -> 3 | O32: =IFERROR($M32*N32,0) -> 0 | Q32: =IFERROR($M32*P32,0) -> 0 | S32: =IFERROR($M32*R32,0) -> 0 | U32: =IFERROR($M32*T32,0) -> 0 | W32: =IFERROR($M32*V32,0) -> 0 | Y32: =IFERROR($M32*X32,0) -> 0 | AA32: =IFERROR($M32*Z32,0) -> 0 | AC32: =IFERROR((N32+P32+R32)*M32,"") -> 0 | AD32: =IFERROR(I32*AC32,"") -> 0
A33: 21 | B33: =IF('印刷・FAX 発注書'!B32="","",'印刷・FAX 発注書'!B32) -> 国産生姜 | C33: =IF('印刷・FAX 発注書'!#REF!="","",'印刷・FAX 発注書'!#REF!) -> #REF! | D33: =IF('印刷・FAX 発注書'!#REF!="","",'印刷・FAX 発注書'!#REF!) -> #REF! | E33: =IF('印刷・FAX 発注書'!E32="","",'印刷・FAX 発注書'!E32) -> パック | F33: =IF('印刷・FAX 発注書'!F32="","",'印刷・FAX 発注書'!F32) -> 要冷 | G33: =IF('印刷・FAX 発注書'!G32="","",'印刷・FAX 発注書'!G32) -> 7 | H33: =IF('印刷・FAX 発注書'!H32="","",'印刷・FAX 発注書'!H32) -> 248 | I33: =IFERROR(ROUNDUP(H33*K33,0),"") -> 179 | J33: 1 | K33: =J33-L33 -> 0.72 | L33: ='印刷・FAX 発注書'!L32 -> 0.28 | M33: =IF('印刷・FAX 発注書'!M32="","",'印刷・FAX 発注書'!M32) -> 3 | O33: =IFERROR($M33*N33,0) -> 0 | P33: 1 | Q33: =IFERROR($M33*P33,0) -> 3 | S33: =IFERROR($M33*R33,0) -> 0 | U33: =IFERROR($M33*T33,0) -> 0 | W33: =IFERROR($M33*V33,0) -> 0 | Y33: =IFERROR($M33*X33,0) -> 0 | AA33: =IFERROR($M33*Z33,0) -> 0 | AC33: =IFERROR((N33+P33+R33)*M33,"") -> 3 | AD33: =IFERROR(I33*AC33,"") -> 537
A34: 22 | B34: =IF('印刷・FAX 発注書'!B33="","",'印刷・FAX 発注書'!B33) -> アボカド | C34: =IF('印刷・FAX 発注書'!C31="","",'印刷・FAX 発注書'!C31) | D34: =IF('印刷・FAX 発注書'!D31="","",'印刷・FAX 発注書'!D31) -> 3本 | E34: =IF('印刷・FAX 発注書'!E33="","",'印刷・FAX 発注書'!E33) -> 個 | F34: =IF('印刷・FAX 発注書'!F33="","",'印刷・FAX 発注書'!F33) -> 両方 | G34: =IF('印刷・FAX 発注書'!G33="","",'印刷・FAX 発注書'!G33) -> 5 | H34: =IF('印刷・FAX 発注書'!H33="","",'印刷・FAX 発注書'!H33) -> 168 | I34: =IFERROR(ROUNDUP(H34*K34,0),"") -> 121 | J34: 1 | K34: =J34-L34 -> 0.72 | L34: ='印刷・FAX 発注書'!L33 -> 0.28 | M34: =IF('印刷・FAX 発注書'!M33="","",'印刷・FAX 発注書'!M33) -> 3 | O34: =IFERROR($M34*N34,0) -> 0 | Q34: =IFERROR($M34*P34,0) -> 0 | S34: =IFERROR($M34*R34,0) -> 0 | U34: =IFERROR($M34*T34,0) -> 0 | W34: =IFERROR($M34*V34,0) -> 0 | Y34: =IFERROR($M34*X34,0) -> 0 | AA34: =IFERROR($M34*Z34,0) -> 0 | AC34: =IFERROR((N34+P34+R34)*M34,"") -> 0 | AD34: =IFERROR(I34*AC34,"") -> 0
A35: 23 | B35: =IF('印刷・FAX 発注書'!B34="","",'印刷・FAX 発注書'!B34) -> さつま芋 | C35: =IF('印刷・FAX 発注書'!C32="","",'印刷・FAX 発注書'!C32) | D35: =IF('印刷・FAX 発注書'!D32="","",'印刷・FAX 発注書'!D32) | E35: =IF('印刷・FAX 発注書'!E34="","",'印刷・FAX 発注書'!E34) -> パック | F35: =IF('印刷・FAX 発注書'!F34="","",'印刷・FAX 発注書'!F34) -> 常温 | G35: =IF('印刷・FAX 発注書'!G34="","",'印刷・FAX 発注書'!G34) -> 10 | H35: =IF('印刷・FAX 発注書'!H34="","",'印刷・FAX 発注書'!H34) -> 258 | I35: =IFERROR(ROUNDUP(H35*K35,0),"") -> 186 | J35: 1 | K35: =J35-L35 -> 0.72 | L35: ='印刷・FAX 発注書'!L34 -> 0.28 | M35: =IF('印刷・FAX 発注書'!M34="","",'印刷・FAX 発注書'!M34) -> 3 | O35: =IFERROR($M35*N35,0) -> 0 | Q35: =IFERROR($M35*P35,0) -> 0 | S35: =IFERROR($M35*R35,0) -> 0 | U35: =IFERROR($M35*T35,0) -> 0 | W35: =IFERROR($M35*V35,0) -> 0 | Y35: =IFERROR($M35*X35,0) -> 0 | AA35: =IFERROR($M35*Z35,0) -> 0 | AC35: =IFERROR((N35+P35+R35)*M35,"") -> 0 | AD35: =IFERROR(I35*AC35,"") -> 0
A36: 24 | B36: =IF('印刷・FAX 発注書'!B35="","",'印刷・FAX 発注書'!B35) -> ごぼう | C36: =IF('印刷・FAX 発注書'!C33="","",'印刷・FAX 発注書'!C33) | D36: =IF('印刷・FAX 発注書'!D33="","",'印刷・FAX 発注書'!D33) | E36: =IF('印刷・FAX 発注書'!E35="","",'印刷・FAX 発注書'!E35) | F36: =IF('印刷・FAX 発注書'!F35="","",'印刷・FAX 発注書'!F35) | G36: =IF('印刷・FAX 発注書'!G35="","",'印刷・FAX 発注書'!G35) -> 10 | H36: =IF('印刷・FAX 発注書'!H35="","",'印刷・FAX 発注書'!H35) -> 198 | I36: =IFERROR(ROUNDUP(H36*K36,0),"") -> 143 | J36: 1 | K36: =J36-L36 -> 0.72 | L36: ='印刷・FAX 発注書'!L35 -> 0.28 | M36: =IF('印刷・FAX 発注書'!M35="","",'印刷・FAX 発注書'!M35) -> 2 | O36: =IFERROR($M36*N36,0) -> 0 | Q36: =IFERROR($M36*P36,0) -> 0 | S36: =IFERROR($M36*R36,0) -> 0 | U36: =IFERROR($M36*T36,0) -> 0 | W36: =IFERROR($M36*V36,0) -> 0 | Y36: =IFERROR($M36*X36,0) -> 0 | AA36: =IFERROR($M36*Z36,0) -> 0 | AC36: =IFERROR((N36+P36+R36)*M36,"") -> 0 | AD36: =IFERROR(I36*AC36,"") -> 0
A37: 25 | B37: =IF('印刷・FAX 発注書'!B36="","",'印刷・FAX 発注書'!B36) | C37: =IF('印刷・FAX 発注書'!C34="","",'印刷・FAX 発注書'!C34) | D37: =IF('印刷・FAX 発注書'!D34="","",'印刷・FAX 発注書'!D34) | E37: =IF('印刷・FAX 発注書'!E36="","",'印刷・FAX 発注書'!E36) | F37: =IF('印刷・FAX 発注書'!F36="","",'印刷・FAX 発注書'!F36) -> 要冷 | G37: =IF('印刷・FAX 発注書'!G36="","",'印刷・FAX 発注書'!G36) -> 5 | H37: =IF('印刷・FAX 発注書'!H36="","",'印刷・FAX 発注書'!H36) | I37: =IFERROR(ROUNDUP(H37*K37,0),"") | J37: 1 | K37: =J37-L37 -> 0.72 | L37: ='印刷・FAX 発注書'!L36 -> 0.28 | M37: =IF('印刷・FAX 発注書'!M36="","",'印刷・FAX 発注書'!M36) -> 3 | O37: =IFERROR($M37*N37,0) -> 0 | Q37: =IFERROR($M37*P37,0) -> 0 | S37: =IFERROR($M37*R37,0) -> 0 | U37: =IFERROR($M37*T37,0) -> 0 | W37: =IFERROR($M37*V37,0) -> 0 | Y37: =IFERROR($M37*X37,0) -> 0 | AA37: =IFERROR($M37*Z37,0) -> 0 | AC37: =IFERROR((N37+P37+R37)*M37,"") -> 0 | AD37: =IFERROR(I37*AC37,"")
A38: 26 | B38: =IF('印刷・FAX 発注書'!B37="","",'印刷・FAX 発注書'!B37) -> えのき茸 | C38: =IF('印刷・FAX 発注書'!C35="","",'印刷・FAX 発注書'!C35) | D38: =IF('印刷・FAX 発注書'!D35="","",'印刷・FAX 発注書'!D35) | E38: =IF('印刷・FAX 発注書'!E37="","",'印刷・FAX 発注書'!E37) | F38: =IF('印刷・FAX 発注書'!F37="","",'印刷・FAX 発注書'!F37) | G38: =IF('印刷・FAX 発注書'!G37="","",'印刷・FAX 発注書'!G37) -> 5 | H38: =IF('印刷・FAX 発注書'!H37="","",'印刷・FAX 発注書'!H37) -> 178 | I38: =IFERROR(ROUNDUP(H38*K38,0),"") -> 129 | J38: 1 | K38: =J38-L38 -> 0.72 | L38: ='印刷・FAX 発注書'!L37 -> 0.28 | M38: =IF('印刷・FAX 発注書'!M37="","",'印刷・FAX 発注書'!M37) -> 3 | O38: =IFERROR($M38*N38,0) -> 0 | Q38: =IFERROR($M38*P38,0) -> 0 | S38: =IFERROR($M38*R38,0) -> 0 | U38: =IFERROR($M38*T38,0) -> 0 | W38: =IFERROR($M38*V38,0) -> 0 | Y38: =IFERROR($M38*X38,0) -> 0 | AA38: =IFERROR($M38*Z38,0) -> 0 | AC38: =IFERROR((N38+P38+R38)*M38,"") -> 0 | AD38: =IFERROR(I38*AC38,"") -> 0
A39: 27 | B39: =IF('印刷・FAX 発注書'!B38="","",'印刷・FAX 発注書'!B38) -> しめじ | C39: =IF('印刷・FAX 発注書'!C36="","",'印刷・FAX 発注書'!C36) | D39: =IF('印刷・FAX 発注書'!D36="","",'印刷・FAX 発注書'!D36) | E39: =IF('印刷・FAX 発注書'!E38="","",'印刷・FAX 発注書'!E38) | F39: =IF('印刷・FAX 発注書'!F38="","",'印刷・FAX 発注書'!F38) | G39: =IF('印刷・FAX 発注書'!G38="","",'印刷・FAX 発注書'!G38) -> 5 | H39: =IF('印刷・FAX 発注書'!H38="","",'印刷・FAX 発注書'!H38) -> 148 | I39: =IFERROR(ROUNDUP(H39*K39,0),"") -> 107 | J39: 1 | K39: =J39-L39 -> 0.72 | L39: ='印刷・FAX 発注書'!L38 -> 0.28 | M39: =IF('印刷・FAX 発注書'!M38="","",'印刷・FAX 発注書'!M38) -> 3 | O39: =IFERROR($M39*N39,0) -> 0 | Q39: =IFERROR($M39*P39,0) -> 0 | S39: =IFERROR($M39*R39,0) -> 0 | U39: =IFERROR($M39*T39,0) -> 0 | W39: =IFERROR($M39*V39,0) -> 0 | Y39: =IFERROR($M39*X39,0) -> 0 | AA39: =IFERROR($M39*Z39,0) -> 0 | AC39: =IFERROR((N39+P39+R39)*M39,"") -> 0 | AD39: =IFERROR(I39*AC39,"") -> 0
A40: 28 | B40: =IF('印刷・FAX 発注書'!B39="","",'印刷・FAX 発注書'!B39) -> しいたけ | C40: =IF('印刷・FAX 発注書'!C37="","",'印刷・FAX 発注書'!C37) | D40: =IF('印刷・FAX 発注書'!D37="","",'印刷・FAX 発注書'!D37) | E40: =IF('印刷・FAX 発注書'!E39="","",'印刷・FAX 発注書'!E39) | F40: =IF('印刷・FAX 発注書'!F39="","",'印刷・FAX 発注書'!F39) | G40: =IF('印刷・FAX 発注書'!G39="","",'印刷・FAX 発注書'!G39) -> 4 | H40: =IF('印刷・FAX 発注書'!H39="","",'印刷・FAX 発注書'!H39) -> 158 | I40: =IFERROR(ROUNDUP(H40*K40,0),"") -> 114 | J40: 1 | K40: =J40-L40 -> 0.72 | L40: ='印刷・FAX 発注書'!L39 -> 0.28 | M40: =IF('印刷・FAX 発注書'!M39="","",'印刷・FAX 発注書'!M39) -> 3 | O40: =IFERROR($M40*N40,0) -> 0 | P40: 1 | Q40: =IFERROR($M40*P40,0) -> 3 | S40: =IFERROR($M40*R40,0) -> 0 | U40: =IFERROR($M40*T40,0) -> 0 | W40: =IFERROR($M40*V40,0) -> 0 | Y40: =IFERROR($M40*X40,0) -> 0 | AA40: =IFERROR($M40*Z40,0) -> 0 | AC40: =IFERROR((N40+P40+R40)*M40,"") -> 3 | AD40: =IFERROR(I40*AC40,"") -> 342
A41: 29 | B41: =IF('印刷・FAX 発注書'!B40="","",'印刷・FAX 発注書'!B40) -> まいたけ | C41: =IF('印刷・FAX 発注書'!C38="","",'印刷・FAX 発注書'!C38) | D41: =IF('印刷・FAX 発注書'!D38="","",'印刷・FAX 発注書'!D38) | E41: =IF('印刷・FAX 発注書'!E40="","",'印刷・FAX 発注書'!E40) | F41: =IF('印刷・FAX 発注書'!F40="","",'印刷・FAX 発注書'!F40) | G41: =IF('印刷・FAX 発注書'!G40="","",'印刷・FAX 発注書'!G40) -> 5 | H41: =IF('印刷・FAX 発注書'!H40="","",'印刷・FAX 発注書'!H40) -> 158 | I41: =IFERROR(ROUNDUP(H41*K41,0),"") -> 114 | J41: 1 | K41: =J41-L41 -> 0.72 | L41: ='印刷・FAX 発注書'!L40 -> 0.28 | M41: =IF('印刷・FAX 発注書'!M40="","",'印刷・FAX 発注書'!M40) -> 2 | O41: =IFERROR($M41*N41,0) -> 0 | P41: 1 | Q41: =IFERROR($M41*P41,0) -> 2 | S41: =IFERROR($M41*R41,0) -> 0 | U41: =IFERROR($M41*T41,0) -> 0 | W41: =IFERROR($M41*V41,0) -> 0 | Y41: =IFERROR($M41*X41,0) -> 0 | AA41: =IFERROR($M41*Z41,0) -> 0 | AC41: =IFERROR((N41+P41+R41)*M41,"") -> 2 | AD41: =IFERROR(I41*AC41,"") -> 228
A42: 30 | B42: =IF('印刷・FAX 発注書'!B41="","",'印刷・FAX 発注書'!B41) -> エリンギ | C42: =IF('印刷・FAX 発注書'!C39="","",'印刷・FAX 発注書'!C39) | D42: =IF('印刷・FAX 発注書'!D39="","",'印刷・FAX 発注書'!D39) | E42: =IF('印刷・FAX 発注書'!E41="","",'印刷・FAX 発注書'!E41) | F42: =IF('印刷・FAX 発注書'!F41="","",'印刷・FAX 発注書'!F41) | G42: =IF('印刷・FAX 発注書'!G41="","",'印刷・FAX 発注書'!G41) -> 5 | H42: =IF('印刷・FAX 発注書'!H41="","",'印刷・FAX 発注書'!H41) -> 158 | I42: =IFERROR(ROUNDUP(H42*K42,0),"") -> 114 | J42: 1 | K42: =J42-L42 -> 0.72 | L42: ='印刷・FAX 発注書'!L41 -> 0.28 | M42: =IF('印刷・FAX 発注書'!M41="","",'印刷・FAX 発注書'!M41) -> 2 | O42: =IFERROR($M42*N42,0) -> 0 | P42: 1 | Q42: =IFERROR($M42*P42,0) -> 2 | S42: =IFERROR($M42*R42,0) -> 0 | U42: =IFERROR($M42*T42,0) -> 0 | W42: =IFERROR($M42*V42,0) -> 0 | Y42: =IFERROR($M42*X42,0) -> 0 | AA42: =IFERROR($M42*Z42,0) -> 0 | AC42: =IFERROR((N42+P42+R42)*M42,"") -> 2 | AD42: =IFERROR(I42*AC42,"") -> 228
A43: 31 | B43: =IF('印刷・FAX 発注書'!B42="","",'印刷・FAX 発注書'!B42) -> なめこ | C43: =IF('印刷・FAX 発注書'!C40="","",'印刷・FAX 発注書'!C40) | D43: =IF('印刷・FAX 発注書'!D40="","",'印刷・FAX 発注書'!D40) | E43: =IF('印刷・FAX 発注書'!E42="","",'印刷・FAX 発注書'!E42) -> 100ｇ | F43: =IF('印刷・FAX 発注書'!F42="","",'印刷・FAX 発注書'!F42) -> 要冷 | G43: =IF('印刷・FAX 発注書'!G42="","",'印刷・FAX 発注書'!G42) -> 5 | H43: =IF('印刷・FAX 発注書'!H42="","",'印刷・FAX 発注書'!H42) -> 108 | I43: =IFERROR(ROUNDUP(H43*K43,0),"") -> 78 | J43: 1 | K43: =J43-L43 -> 0.72 | L43: ='印刷・FAX 発注書'!L42 -> 0.28 | M43: =IF('印刷・FAX 発注書'!M42="","",'印刷・FAX 発注書'!M42) -> 3 | O43: =IFERROR($M43*N43,0) -> 0 | Q43: =IFERROR($M43*P43,0) -> 0 | S43: =IFERROR($M43*R43,0) -> 0 | U43: =IFERROR($M43*T43,0) -> 0 | W43: =IFERROR($M43*V43,0) -> 0 | Y43: =IFERROR($M43*X43,0) -> 0 | AA43: =IFERROR($M43*Z43,0) -> 0 | AC43: =IFERROR((N43+P43+R43)*M43,"") -> 0 | AD43: =IFERROR(I43*AC43,"") -> 0
A44: 32 | B44: =IF('印刷・FAX 発注書'!B43="","",'印刷・FAX 発注書'!B43) -> 中国産ニンニク | C44: =IF('印刷・FAX 発注書'!C41="","",'印刷・FAX 発注書'!C41) | D44: =IF('印刷・FAX 発注書'!D41="","",'印刷・FAX 発注書'!D41) | E44: =IF('印刷・FAX 発注書'!E43="","",'印刷・FAX 発注書'!E43) -> 3個入り | F44: =IF('印刷・FAX 発注書'!F43="","",'印刷・FAX 発注書'!F43) -> 常温 | G44: =IF('印刷・FAX 発注書'!G43="","",'印刷・FAX 発注書'!G43) -> 15 | H44: =IF('印刷・FAX 発注書'!H43="","",'印刷・FAX 発注書'!H43) -> 168 | I44: =IFERROR(ROUNDUP(H44*K44,0),"") -> 121 | J44: 1 | K44: =J44-L44 -> 0.72 | L44: ='印刷・FAX 発注書'!L43 -> 0.28 | M44: =IF('印刷・FAX 発注書'!M43="","",'印刷・FAX 発注書'!M43) -> 3 | O44: =IFERROR($M44*N44,0) -> 0 | Q44: =IFERROR($M44*P44,0) -> 0 | S44: =IFERROR($M44*R44,0) -> 0 | U44: =IFERROR($M44*T44,0) -> 0 | W44: =IFERROR($M44*V44,0) -> 0 | Y44: =IFERROR($M44*X44,0) -> 0 | AA44: =IFERROR($M44*Z44,0) -> 0 | AC44: =IFERROR((N44+P44+R44)*M44,"") -> 0 | AD44: =IFERROR(I44*AC44,"") -> 0
A45: 33 | B45: =IF('印刷・FAX 発注書'!B44="","",'印刷・FAX 発注書'!B44) -> レモン | C45: =IF('印刷・FAX 発注書'!C42="","",'印刷・FAX 発注書'!C42) | D45: =IF('印刷・FAX 発注書'!D42="","",'印刷・FAX 発注書'!D42) | E45: =IF('印刷・FAX 発注書'!E44="","",'印刷・FAX 発注書'!E44) | F45: =IF('印刷・FAX 発注書'!F44="","",'印刷・FAX 発注書'!F44) -> 両方 | G45: =IF('印刷・FAX 発注書'!G44="","",'印刷・FAX 発注書'!G44) -> 15 | H45: =IF('印刷・FAX 発注書'!H44="","",'印刷・FAX 発注書'!H44) -> 138 | I45: =IFERROR(ROUNDUP(H45*K45,0),"") -> 100 | J45: 1 | K45: =J45-L45 -> 0.72 | L45: ='印刷・FAX 発注書'!L44 -> 0.28 | M45: =IF('印刷・FAX 発注書'!M44="","",'印刷・FAX 発注書'!M44) -> 3 | O45: =IFERROR($M45*N45,0) -> 0 | Q45: =IFERROR($M45*P45,0) -> 0 | S45: =IFERROR($M45*R45,0) -> 0 | U45: =IFERROR($M45*T45,0) -> 0 | W45: =IFERROR($M45*V45,0) -> 0 | Y45: =IFERROR($M45*X45,0) -> 0 | AA45: =IFERROR($M45*Z45,0) -> 0 | AC45: =IFERROR((N45+P45+R45)*M45,"") -> 0 | AD45: =IFERROR(I45*AC45,"") -> 0
A46: 34 | B46: =IF('印刷・FAX 発注書'!B45="","",'印刷・FAX 発注書'!B45) -> 甘夏 | C46: =IF('印刷・FAX 発注書'!C43="","",'印刷・FAX 発注書'!C43) | D46: =IF('印刷・FAX 発注書'!D43="","",'印刷・FAX 発注書'!D43) | E46: =IF('印刷・FAX 発注書'!E45="","",'印刷・FAX 発注書'!E45) -> パック | F46: =IF('印刷・FAX 発注書'!F45="","",'印刷・FAX 発注書'!F45) -> 要冷 | G46: =IF('印刷・FAX 発注書'!G45="","",'印刷・FAX 発注書'!G45) -> 5 | H46: =IF('印刷・FAX 発注書'!H45="","",'印刷・FAX 発注書'!H45) -> 238 | I46: =IFERROR(ROUNDUP(H46*K46,0),"") -> 172 | J46: 1 | K46: =J46-L46 -> 0.72 | L46: ='印刷・FAX 発注書'!L45 -> 0.28 | M46: =IF('印刷・FAX 発注書'!M45="","",'印刷・FAX 発注書'!M45) -> 3 | O46: =IFERROR($M46*N46,0) -> 0 | Q46: =IFERROR($M46*P46,0) -> 0 | S46: =IFERROR($M46*R46,0) -> 0 | U46: =IFERROR($M46*T46,0) -> 0 | W46: =IFERROR($M46*V46,0) -> 0 | Y46: =IFERROR($M46*X46,0) -> 0 | AA46: =IFERROR($M46*Z46,0) -> 0 | AC46: =IFERROR((N46+P46+R46)*M46,"") -> 0 | AD46: =IFERROR(I46*AC46,"") -> 0
A47: 35 | B47: =IF('印刷・FAX 発注書'!B46="","",'印刷・FAX 発注書'!B46) -> 大葉しそ | C47: =IF('印刷・FAX 発注書'!C44="","",'印刷・FAX 発注書'!C44) -> 米国 | D47: =IF('印刷・FAX 発注書'!D44="","",'印刷・FAX 発注書'!D44) | E47: =IF('印刷・FAX 発注書'!E46="","",'印刷・FAX 発注書'!E46) -> ﾊﾟｯｸ | F47: =IF('印刷・FAX 発注書'!F46="","",'印刷・FAX 発注書'!F46) | G47: =IF('印刷・FAX 発注書'!G46="","",'印刷・FAX 発注書'!G46) -> 4 | H47: =IF('印刷・FAX 発注書'!H46="","",'印刷・FAX 発注書'!H46) -> 128 | I47: =IFERROR(ROUNDUP(H47*K47,0),"") -> 93 | J47: 1 | K47: =J47-L47 -> 0.72 | L47: ='印刷・FAX 発注書'!L46 -> 0.28 | M47: =IF('印刷・FAX 発注書'!M46="","",'印刷・FAX 発注書'!M46) -> 3 | O47: =IFERROR($M47*N47,0) -> 0 | P47: 1 | Q47: =IFERROR($M47*P47,0) -> 3 | S47: =IFERROR($M47*R47,0) -> 0 | U47: =IFERROR($M47*T47,0) -> 0 | W47: =IFERROR($M47*V47,0) -> 0 | Y47: =IFERROR($M47*X47,0) -> 0 | AA47: =IFERROR($M47*Z47,0) -> 0 | AC47: =IFERROR((N47+P47+R47)*M47,"") -> 3 | AD47: =IFERROR(I47*AC47,"") -> 279
A48: 36 | B48: =IF('印刷・FAX 発注書'!B47="","",'印刷・FAX 発注書'!B47) -> 温州みかん | C48: =IF('印刷・FAX 発注書'!C45="","",'印刷・FAX 発注書'!C45) | D48: =IF('印刷・FAX 発注書'!D45="","",'印刷・FAX 発注書'!D45) -> 2個 | E48: =IF('印刷・FAX 発注書'!E47="","",'印刷・FAX 発注書'!E47) -> パック | F48: =IF('印刷・FAX 発注書'!F47="","",'印刷・FAX 発注書'!F47) -> 要冷 | G48: =IF('印刷・FAX 発注書'!G47="","",'印刷・FAX 発注書'!G47) -> 5 | H48: =IF('印刷・FAX 発注書'!H47="","",'印刷・FAX 発注書'!H47) -> 378 | I48: =IFERROR(ROUNDUP(H48*K48,0),"") -> 273 | J48: 1 | K48: =J48-L48 -> 0.72 | L48: ='印刷・FAX 発注書'!L47 -> 0.28 | M48: =IF('印刷・FAX 発注書'!M47="","",'印刷・FAX 発注書'!M47) -> 3 | O48: =IFERROR($M48*N48,0) -> 0 | Q48: =IFERROR($M48*P48,0) -> 0 | S48: =IFERROR($M48*R48,0) -> 0 | U48: =IFERROR($M48*T48,0) -> 0 | W48: =IFERROR($M48*V48,0) -> 0 | Y48: =IFERROR($M48*X48,0) -> 0 | AA48: =IFERROR($M48*Z48,0) -> 0 | AC48: =IFERROR((N48+P48+R48)*M48,"") -> 0 | AD48: =IFERROR(I48*AC48,"") -> 0
A49: 37 | B49: =IF('印刷・FAX 発注書'!B48="","",'印刷・FAX 発注書'!B48) -> ソルダム | C49: =IF('印刷・FAX 発注書'!#REF!="","",'印刷・FAX 発注書'!#REF!) -> #REF! | D49: =IF('印刷・FAX 発注書'!#REF!="","",'印刷・FAX 発注書'!#REF!) -> #REF! | E49: =IF('印刷・FAX 発注書'!E48="","",'印刷・FAX 発注書'!E48) -> パック | F49: =IF('印刷・FAX 発注書'!F48="","",'印刷・FAX 発注書'!F48) | G49: =IF('印刷・FAX 発注書'!G48="","",'印刷・FAX 発注書'!G48) -> 7 | H49: =IF('印刷・FAX 発注書'!H48="","",'印刷・FAX 発注書'!H48) -> 398 | I49: =IFERROR(ROUNDUP(H49*K49,0),"") -> 287 | J49: 1 | K49: =J49-L49 -> 0.72 | L49: ='印刷・FAX 発注書'!L48 -> 0.28 | M49: =IF('印刷・FAX 発注書'!M48="","",'印刷・FAX 発注書'!M48) -> 2 | O49: =IFERROR($M49*N49,0) -> 0 | Q49: =IFERROR($M49*P49,0) -> 0 | S49: =IFERROR($M49*R49,0) -> 0 | U49: =IFERROR($M49*T49,0) -> 0 | W49: =IFERROR($M49*V49,0) -> 0 | Y49: =IFERROR($M49*X49,0) -> 0 | AA49: =IFERROR($M49*Z49,0) -> 0 | AC49: =IFERROR((N49+P49+R49)*M49,"") -> 0 | AD49: =IFERROR(I49*AC49,"") -> 0
...

Sheet 仙台高野原店
G1: №
B2: 納 品 書 | C2: ='入力 発注書'!G8 -> 46224
D4: 仙台市太白区秋保湯元字寺田原45-11
D5: 有 限 会 社 マ ル カ
E6: TEL 022-398-2408
E7: FAX 022-397-2817
B8: ファミリーマート | C8: 仙台高野原店 様
B9: 下記のとおり納品いたしました
B11: 税込合計金額 ( 原価合計） | C11: =G72+G73 -> 3398 | F11: （消費税額等）
B12: 品 名 | C12: 単 価 | E12: 数 量 | F12: 金 額
C13: 売価 | D13: 原価 | F13: 売価 | G13: 原価
A14: ='入力 発注書'!A13 -> 1 | B14: ='入力 発注書'!B13 -> バナナ | C14: ='印刷・FAX 発注書'!H13 -> 98 | D14: ='印刷・FAX 発注書'!I13 -> 71 | E14: ='入力 発注書'!Q13 -> 0 | F14: =$E14*C14 -> 0 | G14: =$E14*D14 -> 0
A15: ='入力 発注書'!A14 -> 2 | B15: ='入力 発注書'!B14 -> バナナ | C15: ='印刷・FAX 発注書'!H14 -> 216 | D15: ='印刷・FAX 発注書'!I14 -> 156 | E15: ='入力 発注書'!Q14 -> 5 | F15: =$E15*C15 -> 1080 | G15: =E15*D15 -> 780
A16: ='入力 発注書'!A15 -> 3 | B16: ='入力 発注書'!B15 -> 新玉ねぎ | C16: ='印刷・FAX 発注書'!H15 -> 158 | D16: ='印刷・FAX 発注書'!I15 -> 114 | E16: ='入力 発注書'!Q15 -> 0 | F16: =$E16*C16 -> 0 | G16: =E16*D16 -> 0
A17: ='入力 発注書'!A16 -> 4 | B17: ='入力 発注書'!B16 -> 新玉ねぎ | C17: ='印刷・FAX 発注書'!H15 -> 158 | D17: ='印刷・FAX 発注書'!I15 -> 114 | E17: ='入力 発注書'!Q16 -> 5 | F17: =$E17*C17 -> 790 | G17: =E17*D17 -> 570
A18: ='入力 発注書'!A17 -> 5 | B18: ='入力 発注書'!B17 -> 人参（冷蔵保存） | C18: ='印刷・FAX 発注書'!H16 -> 128 | D18: ='印刷・FAX 発注書'!I16 -> 93 | E18: ='入力 発注書'!Q17 -> 0 | F18: =$E18*C18 -> 0 | G18: =E18*D18 -> 0
A19: ='入力 発注書'!A18 -> 6 | B19: ='入力 発注書'!B18 | C19: ='印刷・FAX 発注書'!H17 -> 0 | D19: ='印刷・FAX 発注書'!I17 -> 0 | E19: ='入力 発注書'!Q18 -> 0 | F19: =$E19*C19 -> 0 | G19: =E19*D19 -> 0
A20: ='入力 発注書'!A19 -> 7 | B20: ='入力 発注書'!B19 -> じゃが芋 | C20: ='印刷・FAX 発注書'!H18 -> 128 | D20: ='印刷・FAX 発注書'!I18 -> 93 | E20: ='入力 発注書'!Q19 -> 0 | F20: =$E20*C20 -> 0 | G20: =E20*D20 -> 0
A21: ='入力 発注書'!A20 -> 8 | B21: ='入力 発注書'!B20 -> 胡瓜 | C21: ='印刷・FAX 発注書'!H19 -> 138 | D21: ='印刷・FAX 発注書'!I19 -> 100 | E21: ='入力 発注書'!Q20 -> 0 | F21: =$E21*C21 -> 0 | G21: =E21*D21 -> 0
A22: ='入力 発注書'!A21 -> 9 | B22: ='入力 発注書'!B21 -> トマト | C22: ='印刷・FAX 発注書'!H20 -> 238 | D22: ='印刷・FAX 発注書'!I20 -> 215 | E22: ='入力 発注書'!Q21 -> 0 | F22: =$E22*C22 -> 0 | G22: =E22*D22 -> 0
A23: ='入力 発注書'!A22 -> 10 | B23: ='入力 発注書'!B22 -> レタス | C23: ='印刷・FAX 発注書'!H21 -> 258 | D23: ='印刷・FAX 発注書'!I21 -> 186 | E23: ='入力 発注書'!Q22 -> 0 | F23: =$E23*C23 -> 0 | G23: =E23*D23 -> 0
A24: ='入力 発注書'!A23 -> 11 | B24: ='入力 発注書'!B23 -> ミニトマト | C24: ='印刷・FAX 発注書'!H22 -> 378 | D24: ='印刷・FAX 発注書'!I22 -> 287 | E24: ='入力 発注書'!Q23 -> 0 | F24: =$E24*C24 -> 0 | G24: =E24*D24 -> 0
A25: ='入力 発注書'!A24 -> 12 | B25: ='入力 発注書'!B24 -> ネギ(１本） | C25: ='印刷・FAX 発注書'!H23 -> 108 | D25: ='印刷・FAX 発注書'!I23 -> 78 | E25: ='入力 発注書'!Q24 -> 3 | F25: =$E25*C25 -> 324 | G25: =E25*D25 -> 234
A26: ='入力 発注書'!A25 -> 13 | B26: ='入力 発注書'!B25 -> ピーマン | C26: ='印刷・FAX 発注書'!H24 -> 198 | D26: ='印刷・FAX 発注書'!I24 -> 143 | E26: ='入力 発注書'!Q25 -> 0 | F26: =$E26*C26 -> 0 | G26: =E26*D26 -> 0
A27: ='入力 発注書'!A26 -> 14 | B27: ='入力 発注書'!B26 -> キャベツ | C27: ='印刷・FAX 発注書'!H25 -> 138 | D27: ='印刷・FAX 発注書'!I25 -> 100 | E27: ='入力 発注書'!Q26 -> 2 | F27: =$E27*C27 -> 276 | G27: =E27*D27 -> 200
A28: ='入力 発注書'!A27 -> 15 | B28: ='入力 発注書'!B27 -> キャベツ | C28: ='印刷・FAX 発注書'!H26 -> 358 | D28: ='印刷・FAX 発注書'!I26 -> 258 | E28: ='入力 発注書'!Q27 -> 0 | F28: =$E28*C28 -> 0 | G28: =E28*D28 -> 0
... A70: ='入力 発注書'!A69 -> 57 | B70: ='入力 発注書'!B69 -> 0 | C70: ='印刷・FAX 発注書'!H68 -> 0 | D70: ='印刷・FAX 発注書'!I68 -> 0 | E70: ='入力 発注書'!Q69 -> 0 | F70: =$E70*C70 -> 0 | G70: =E70*D70 -> 0
A71: ='入力 発注書'!A70 -> 58 | B71: ='入力 発注書'!B70 -> 送料 | D71: ='入力 発注書'!P70 -> 0 | E71: ='入力 発注書'!Q70 -> 0 | F71: 0 | G71: =E71*D71 -> 0
B72: 合計(税込み) | D72: 8％対象 | F72: =SUM(F14:F70) -> 4704 | G72: =SUM(G14:G70) -> 3398
D73: 10％対象 | F73: =F71 -> 0 | G73: =G71 -> 0
B74: * 印は軽減税率8％対象商品となります。

Sheet 栗生4丁目店
G1: №
B2: 納 品 書 | C2: ='入力 発注書'!G8 -> 46224
D4: 仙台市太白区秋保湯元字寺田原45-11
D5: 有 限 会 社 マ ル カ
E6: TEL 022-398-2408
E7: FAX 022-397-2817
B8: ファミリーマート | C8: 栗生4丁目店 様
B9: 下記のとおり納品いたしました
B11: 税込合計金額 ( 原価合計） | C11: =G72+G73 -> 0 | F11: （消費税額等）
B12: 品 名 | C12: 単 価 | E12: 数 量 | F12: 金 額
C13: 売価 | D13: 原価 | F13: 売価 | G13: 原価
A14: ='入力 発注書'!A13 -> 1 | B14: ='入力 発注書'!B13 -> バナナ | C14: ='印刷・FAX 発注書'!H13 -> 98 | D14: ='印刷・FAX 発注書'!I13 -> 71 | E14: ='入力 発注書'!S13 -> 0 | F14: =$E14*C14 -> 0 | G14: =$E14*D14 -> 0
A15: ='入力 発注書'!A14 -> 2 | B15: ='入力 発注書'!B14 -> バナナ | C15: ='印刷・FAX 発注書'!H14 -> 216 | D15: ='印刷・FAX 発注書'!I14 -> 156 | E15: ='入力 発注書'!S14 -> 0 | F15: =$E15*C15 -> 0 | G15: =E15*D15 -> 0
A16: ='入力 発注書'!A15 -> 3 | B16: ='入力 発注書'!B15 -> 新玉ねぎ | C16: ='印刷・FAX 発注書'!H15 -> 158 | D16: ='印刷・FAX 発注書'!I15 -> 114 | E16: ='入力 発注書'!S15 -> 0 | F16: =$E16*C16 -> 0 | G16: =E16*D16 -> 0
A17: ='入力 発注書'!A16 -> 4 | B17: ='入力 発注書'!B16 -> 新玉ねぎ | C17: ='印刷・FAX 発注書'!H15 -> 158 | D17: ='印刷・FAX 発注書'!I15 -> 114 | E17: ='入力 発注書'!S16 -> 0 | F17: =$E17*C17 -> 0 | G17: =E17*D17 -> 0
A18: ='入力 発注書'!A17 -> 5 | B18: ='入力 発注書'!B17 -> 人参（冷蔵保存） | C18: ='印刷・FAX 発注書'!H16 -> 128 | D18: ='印刷・FAX 発注書'!I16 -> 93 | E18: ='入力 発注書'!S17 -> 0 | F18: =$E18*C18 -> 0 | G18: =E18*D18 -> 0
A19: ='入力 発注書'!A18 -> 6 | B19: ='入力 発注書'!B18 | C19: ='印刷・FAX 発注書'!H17 -> 0 | D19: ='印刷・FAX 発注書'!I17 -> 0 | E19: ='入力 発注書'!S18 -> 0 | F19: =$E19*C19 -> 0 | G19: =E19*D19 -> 0
A20: ='入力 発注書'!A19 -> 7 | B20: ='入力 発注書'!B19 -> じゃが芋 | C20: ='印刷・FAX 発注書'!H18 -> 128 | D20: ='印刷・FAX 発注書'!I18 -> 93 | E20: ='入力 発注書'!S19 -> 0 | F20: =$E20*C20 -> 0 | G20: =E20*D20 -> 0
A21: ='入力 発注書'!A20 -> 8 | B21: ='入力 発注書'!B20 -> 胡瓜 | C21: ='印刷・FAX 発注書'!H19 -> 138 | D21: ='印刷・FAX 発注書'!I19 -> 100 | E21: ='入力 発注書'!S20 -> 0 | F21: =$E21*C21 -> 0 | G21: =E21*D21 -> 0
A22: ='入力 発注書'!A21 -> 9 | B22: ='入力 発注書'!B21 -> トマト | C22: ='印刷・FAX 発注書'!H20 -> 238 | D22: ='印刷・FAX 発注書'!I20 -> 215 | E22: ='入力 発注書'!S21 -> 0 | F22: =$E22*C22 -> 0 | G22: =E22*D22 -> 0
A23: ='入力 発注書'!A22 -> 10 | B23: ='入力 発注書'!B22 -> レタス | C23: ='印刷・FAX 発注書'!H21 -> 258 | D23: ='印刷・FAX 発注書'!I21 -> 186 | E23: ='入力 発注書'!S22 -> 0 | F23: =$E23*C23 -> 0 | G23: =E23*D23 -> 0
A24: ='入力 発注書'!A23 -> 11 | B24: ='入力 発注書'!B23 -> ミニトマト | C24: ='印刷・FAX 発注書'!H22 -> 378 | D24: ='印刷・FAX 発注書'!I22 -> 287 | E24: ='入力 発注書'!S23 -> 0 | F24: =$E24*C24 -> 0 | G24: =E24*D24 -> 0
A25: ='入力 発注書'!A24 -> 12 | B25: ='入力 発注書'!B24 -> ネギ(１本） | C25: ='印刷・FAX 発注書'!H23 -> 108 | D25: ='印刷・FAX 発注書'!I23 -> 78 | E25: ='入力 発注書'!S24 -> 0 | F25: =$E25*C25 -> 0 | G25: =E25*D25 -> 0
A26: ='入力 発注書'!A25 -> 13 | B26: ='入力 発注書'!B25 -> ピーマン | C26: ='印刷・FAX 発注書'!H24 -> 198 | D26: ='印刷・FAX 発注書'!I24 -> 143 | E26: ='入力 発注書'!S25 -> 0 | F26: =$E26*C26 -> 0 | G26: =E26*D26 -> 0
A27: ='入力 発注書'!A26 -> 14 | B27: ='入力 発注書'!B26 -> キャベツ | C27: ='印刷・FAX 発注書'!H25 -> 138 | D27: ='印刷・FAX 発注書'!I25 -> 100 | E27: ='入力 発注書'!S26 -> 0 | F27: =$E27*C27 -> 0 | G27: =E27*D27 -> 0
A28: ='入力 発注書'!A27 -> 15 | B28: ='入力 発注書'!B27 -> キャベツ | C28: ='印刷・FAX 発注書'!H26 -> 358 | D28: ='印刷・FAX 発注書'!I26 -> 258 | E28: ='入力 発注書'!S27 -> 0 | F28: =$E28*C28 -> 0 | G28: =E28*D28 -> 0
... A70: ='入力 発注書'!A69 -> 57 | B70: ='入力 発注書'!B69 -> 0 | C70: ='印刷・FAX 発注書'!H68 -> 0 | D70: ='印刷・FAX 発注書'!I68 -> 0 | E70: ='入力 発注書'!S69 -> 0 | F70: =$E70*C70 -> 0 | G70: =E70*D70 -> 0
A71: ='入力 発注書'!A70 -> 58 | B71: ='入力 発注書'!B70 -> 送料 | D71: ='入力 発注書'!R70 -> 0 | E71: ='入力 発注書'!S70 -> 0 | F71: 0 | G71: =E71*D71 -> 0
B72: 合計(税込み) | D72: 8％対象 | F72: =SUM(F14:F70) -> 0 | G72: =SUM(G14:G70) -> 0
D73: 10％対象 | F73: 0 | G73: =G71 -> 0
B74: * 印は軽減税率8％対象商品となります。

Sheet AA
G1: №
B2: 納 品 書 | C2: ='入力 発注書'!G8 -> 46224
D4: 仙台市太白区秋保湯元字寺田原45-11
D5: 有 限 会 社 マ ル カ
E6: TEL 022-398-2408
E7: FAX 022-397-2817
B8: ファミリーマート | C8: 堤町店 様
B9: 下記のとおり納品いたしました
B11: 税込合計金額 ( 原価合計） | C11: =G72+G73 -> #REF! | F11: （消費税額等）
B12: 品 名 | C12: 単 価 | E12: 数 量 | F12: 金 額
C13: 売価 | D13: 原価 | F13: 売価 | G13: 原価
A14: ='入力 発注書'!A13 -> 1 | B14: ='入力 発注書'!B13 -> バナナ | C14: ='印刷・FAX 発注書'!H13 -> 98 | D14: ='印刷・FAX 発注書'!I13 -> 71 | E14: ='入力 発注書'!U13 -> 0 | F14: =$E14*C14 -> 0 | G14: =$E14*D14 -> 0
A15: ='入力 発注書'!A14 -> 2 | B15: ='入力 発注書'!B14 -> バナナ | C15: ='印刷・FAX 発注書'!H14 -> 216 | D15: ='印刷・FAX 発注書'!I14 -> 156 | E15: ='入力 発注書'!U14 -> 0 | F15: =$E15*C15 -> 0 | G15: =E15*D15 -> 0
A16: ='入力 発注書'!A15 -> 3 | B16: ='入力 発注書'!B15 -> 新玉ねぎ | C16: ='印刷・FAX 発注書'!#REF! -> #REF! | D16: ='印刷・FAX 発注書'!#REF! -> #REF! | E16: ='入力 発注書'!U15 -> 0 | F16: =$E16*C16 -> #REF! | G16: =E16*D16 -> #REF!
A17: ='入力 発注書'!A16 -> 4 | B17: ='入力 発注書'!B16 -> 新玉ねぎ | C17: ='印刷・FAX 発注書'!H15 -> 158 | D17: ='印刷・FAX 発注書'!I15 -> 114 | E17: ='入力 発注書'!U16 -> 0 | F17: =$E17*C17 -> 0 | G17: =E17*D17 -> 0
A18: ='入力 発注書'!A17 -> 5 | B18: ='入力 発注書'!B17 -> 人参（冷蔵保存） | C18: ='印刷・FAX 発注書'!H16 -> 128 | D18: ='印刷・FAX 発注書'!I16 -> 93 | E18: ='入力 発注書'!U17 -> 0 | F18: =$E18*C18 -> 0 | G18: =E18*D18 -> 0
A19: ='入力 発注書'!A18 -> 6 | B19: ='入力 発注書'!B18 | C19: ='印刷・FAX 発注書'!H17 -> 0 | D19: ='印刷・FAX 発注書'!I17 -> 0 | E19: ='入力 発注書'!U18 -> 0 | F19: =$E19*C19 -> 0 | G19: =E19*D19 -> 0
A20: ='入力 発注書'!A19 -> 7 | B20: ='入力 発注書'!B19 -> じゃが芋 | C20: ='印刷・FAX 発注書'!H18 -> 128 | D20: ='印刷・FAX 発注書'!I18 -> 93 | E20: ='入力 発注書'!U19 -> 0 | F20: =$E20*C20 -> 0 | G20: =E20*D20 -> 0
A21: ='入力 発注書'!A20 -> 8 | B21: ='入力 発注書'!B20 -> 胡瓜 | C21: ='印刷・FAX 発注書'!H19 -> 138 | D21: ='印刷・FAX 発注書'!I19 -> 100 | E21: ='入力 発注書'!U20 -> 0 | F21: =$E21*C21 -> 0 | G21: =E21*D21 -> 0
A22: ='入力 発注書'!A21 -> 9 | B22: ='入力 発注書'!B21 -> トマト | C22: ='印刷・FAX 発注書'!H20 -> 238 | D22: ='印刷・FAX 発注書'!I20 -> 215 | E22: ='入力 発注書'!U21 -> 0 | F22: =$E22*C22 -> 0 | G22: =E22*D22 -> 0
A23: ='入力 発注書'!A22 -> 10 | B23: ='入力 発注書'!B22 -> レタス | C23: ='印刷・FAX 発注書'!H21 -> 258 | D23: ='印刷・FAX 発注書'!I21 -> 186 | E23: ='入力 発注書'!U22 -> 0 | F23: =$E23*C23 -> 0 | G23: =E23*D23 -> 0
A24: ='入力 発注書'!A23 -> 11 | B24: ='入力 発注書'!B23 -> ミニトマト | C24: ='印刷・FAX 発注書'!H22 -> 378 | D24: ='印刷・FAX 発注書'!I22 -> 287 | E24: ='入力 発注書'!U23 -> 0 | F24: =$E24*C24 -> 0 | G24: =E24*D24 -> 0
A25: ='入力 発注書'!A24 -> 12 | B25: ='入力 発注書'!B24 -> ネギ(１本） | C25: ='印刷・FAX 発注書'!H23 -> 108 | D25: ='印刷・FAX 発注書'!I23 -> 78 | E25: ='入力 発注書'!U24 -> 0 | F25: =$E25*C25 -> 0 | G25: =E25*D25 -> 0
A26: ='入力 発注書'!A25 -> 13 | B26: ='入力 発注書'!B25 -> ピーマン | C26: ='印刷・FAX 発注書'!H24 -> 198 | D26: ='印刷・FAX 発注書'!I24 -> 143 | E26: ='入力 発注書'!U25 -> 0 | F26: =$E26*C26 -> 0 | G26: =E26*D26 -> 0
A27: ='入力 発注書'!A26 -> 14 | B27: ='入力 発注書'!B26 -> キャベツ | C27: ='印刷・FAX 発注書'!H25 -> 138 | D27: ='印刷・FAX 発注書'!I25 -> 100 | E27: ='入力 発注書'!U26 -> 0 | F27: =$E27*C27 -> 0 | G27: =E27*D27 -> 0
A28: ='入力 発注書'!A27 -> 15 | B28: ='入力 発注書'!B27 -> キャベツ | C28: ='印刷・FAX 発注書'!H26 -> 358 | D28: ='印刷・FAX 発注書'!I26 -> 258 | E28: ='入力 発注書'!U27 -> 0 | F28: =$E28*C28 -> 0 | G28: =E28*D28 -> 0
... A70: ='入力 発注書'!A69 -> 57 | B70: ='入力 発注書'!B69 -> 0 | C70: ='印刷・FAX 発注書'!H68 -> 0 | D70: ='印刷・FAX 発注書'!I68 -> 0 | E70: ='入力 発注書'!U69 -> 0 | F70: =$E70*C70 -> 0 | G70: =E70*D70 -> 0
A71: ='入力 発注書'!A70 -> 58 | B71: ='入力 発注書'!B70 -> 送料 | D71: ='入力 発注書'!T70 -> 0 | E71: ='入力 発注書'!U70 -> 0 | G71: =E71*D71 -> 0
B72: 合計(税込み) | D72: 8％対象 | F72: =SUM(F14:F70) -> #REF! | G72: =SUM(G14:G70) -> #REF!
D73: 10％対象 | G73: =G71 -> 0
B74: * 印は軽減税率8％対象商品となります。

Sheet BB
G1: №
B2: 納 品 書 | C2: ='入力 発注書'!G8 -> 46224
D4: 仙台市太白区秋保湯元字寺田原45-11
D5: 有 限 会 社 マ ル カ
E6: TEL 022-398-2408
E7: FAX 022-397-2817
B8: ファミリーマート | C8: 広瀬立町店 様
B9: 下記のとおり納品いたしました
B11: 税込合計金額 ( 原価合計） | C11: =G72+G73 -> #REF! | F11: （消費税額等）
B12: 品 名 | C12: 単 価 | E12: 数 量 | F12: 金 額
C13: 売価 | D13: 原価 | F13: 売価 | G13: 原価
A14: ='入力 発注書'!A13 -> 1 | B14: ='入力 発注書'!B13 -> バナナ | C14: ='印刷・FAX 発注書'!H13 -> 98 | D14: ='印刷・FAX 発注書'!I13 -> 71 | E14: ='入力 発注書'!W13 -> 0 | F14: =$E14*C14 -> 0 | G14: =$E14*D14 -> 0
A15: ='入力 発注書'!A14 -> 2 | B15: ='入力 発注書'!B14 -> バナナ | C15: ='印刷・FAX 発注書'!H14 -> 216 | D15: ='印刷・FAX 発注書'!I14 -> 156 | E15: ='入力 発注書'!W14 -> 0 | F15: =$E15*C15 -> 0 | G15: =E15*D15 -> 0
A16: ='入力 発注書'!A15 -> 3 | B16: ='入力 発注書'!B15 -> 新玉ねぎ | C16: ='印刷・FAX 発注書'!#REF! -> #REF! | D16: ='印刷・FAX 発注書'!#REF! -> #REF! | E16: ='入力 発注書'!W15 -> 0 | F16: =$E16*C16 -> #REF! | G16: =E16*D16 -> #REF!
A17: ='入力 発注書'!A16 -> 4 | B17: ='入力 発注書'!B16 -> 新玉ねぎ | C17: ='印刷・FAX 発注書'!H15 -> 158 | D17: ='印刷・FAX 発注書'!I15 -> 114 | E17: ='入力 発注書'!W16 -> 0 | F17: =$E17*C17 -> 0 | G17: =E17*D17 -> 0
A18: ='入力 発注書'!A17 -> 5 | B18: ='入力 発注書'!B17 -> 人参（冷蔵保存） | C18: ='印刷・FAX 発注書'!H16 -> 128 | D18: ='印刷・FAX 発注書'!I16 -> 93 | E18: ='入力 発注書'!W17 -> 0 | F18: =$E18*C18 -> 0 | G18: =E18*D18 -> 0
A19: ='入力 発注書'!A18 -> 6 | B19: ='入力 発注書'!B18 | C19: ='印刷・FAX 発注書'!H17 -> 0 | D19: ='印刷・FAX 発注書'!I17 -> 0 | E19: ='入力 発注書'!W18 -> 0 | F19: =$E19*C19 -> 0 | G19: =E19*D19 -> 0
A20: ='入力 発注書'!A19 -> 7 | B20: ='入力 発注書'!B19 -> じゃが芋 | C20: ='印刷・FAX 発注書'!H18 -> 128 | D20: ='印刷・FAX 発注書'!I18 -> 93 | E20: ='入力 発注書'!W19 -> 0 | F20: =$E20*C20 -> 0 | G20: =E20*D20 -> 0
A21: ='入力 発注書'!A20 -> 8 | B21: ='入力 発注書'!B20 -> 胡瓜 | C21: ='印刷・FAX 発注書'!H19 -> 138 | D21: ='印刷・FAX 発注書'!I19 -> 100 | E21: ='入力 発注書'!W20 -> 0 | F21: =$E21*C21 -> 0 | G21: =E21*D21 -> 0
A22: ='入力 発注書'!A21 -> 9 | B22: ='入力 発注書'!B21 -> トマト | C22: ='印刷・FAX 発注書'!H20 -> 238 | D22: ='印刷・FAX 発注書'!I20 -> 215 | E22: ='入力 発注書'!W21 -> 0 | F22: =$E22*C22 -> 0 | G22: =E22*D22 -> 0
A23: ='入力 発注書'!A22 -> 10 | B23: ='入力 発注書'!B22 -> レタス | C23: ='印刷・FAX 発注書'!H21 -> 258 | D23: ='印刷・FAX 発注書'!I21 -> 186 | E23: ='入力 発注書'!W22 -> 0 | F23: =$E23*C23 -> 0 | G23: =E23*D23 -> 0
A24: ='入力 発注書'!A23 -> 11 | B24: ='入力 発注書'!B23 -> ミニトマト | C24: ='印刷・FAX 発注書'!H22 -> 378 | D24: ='印刷・FAX 発注書'!I22 -> 287 | E24: ='入力 発注書'!W23 -> 0 | F24: =$E24*C24 -> 0 | G24: =E24*D24 -> 0
A25: ='入力 発注書'!A24 -> 12 | B25: ='入力 発注書'!B24 -> ネギ(１本） | C25: ='印刷・FAX 発注書'!H23 -> 108 | D25: ='印刷・FAX 発注書'!I23 -> 78 | E25: ='入力 発注書'!W24 -> 0 | F25: =$E25*C25 -> 0 | G25: =E25*D25 -> 0
A26: ='入力 発注書'!A25 -> 13 | B26: ='入力 発注書'!B25 -> ピーマン | C26: ='印刷・FAX 発注書'!H24 -> 198 | D26: ='印刷・FAX 発注書'!I24 -> 143 | E26: ='入力 発注書'!W25 -> 0 | F26: =$E26*C26 -> 0 | G26: =E26*D26 -> 0
A27: ='入力 発注書'!A26 -> 14 | B27: ='入力 発注書'!B26 -> キャベツ | C27: ='印刷・FAX 発注書'!H25 -> 138 | D27: ='印刷・FAX 発注書'!I25 -> 100 | E27: ='入力 発注書'!W26 -> 0 | F27: =$E27*C27 -> 0 | G27: =E27*D27 -> 0
A28: ='入力 発注書'!A27 -> 15 | B28: ='入力 発注書'!B27 -> キャベツ | C28: ='印刷・FAX 発注書'!H26 -> 358 | D28: ='印刷・FAX 発注書'!I26 -> 258 | E28: ='入力 発注書'!W27 -> 0 | F28: =$E28*C28 -> 0 | G28: =E28*D28 -> 0
... A70: ='入力 発注書'!A69 -> 57 | B70: ='入力 発注書'!B69 -> 0 | C70: ='印刷・FAX 発注書'!H68 -> 0 | D70: ='印刷・FAX 発注書'!I68 -> 0 | E70: ='入力 発注書'!W69 -> 0 | F70: =$E70*C70 -> 0 | G70: =E70*D70 -> 0
A71: ='入力 発注書'!A70 -> 58 | B71: ='入力 発注書'!B70 -> 送料 | D71: ='入力 発注書'!V70 -> 0 | E71: ='入力 発注書'!W70 -> 0 | G71: =E71*D71 -> 0
B72: 合計(税込み) | D72: 8％対象 | F72: =SUM(F14:F70) -> #REF! | G72: =SUM(G14:G70) -> #REF!
D73: 10％対象 | G73: =G71 -> 0
B74: * 印は軽減税率8％対象商品となります。

Sheet A
G1: №
B2: 納 品 書 | C2: ='入力 発注書'!G8 -> 46224
D4: 仙台市太白区秋保湯元字寺田原45-11
D5: 有 限 会 社 マ ル カ
E6: TEL 022-398-2408
E7: FAX 022-397-2817
B8: ファミリーマート | C8: A店 様
B9: 下記のとおり納品いたしました
B11: 税込合計金額 ( 原価合計） | C11: =G72+G73 -> #REF! | F11: （消費税額等）
B12: 品 名 | C12: 単 価 | E12: 数 量 | F12: 金 額
C13: 売価 | D13: 原価 | F13: 売価 | G13: 原価
A14: ='入力 発注書'!A13 -> 1 | B14: ='入力 発注書'!B13 -> バナナ | C14: ='印刷・FAX 発注書'!H13 -> 98 | D14: ='印刷・FAX 発注書'!I13 -> 71 | E14: ='入力 発注書'!Y13 -> 0 | F14: =$E14*C14 -> 0 | G14: =$E14*D14 -> 0
A15: ='入力 発注書'!A14 -> 2 | B15: ='入力 発注書'!B14 -> バナナ | C15: ='印刷・FAX 発注書'!H14 -> 216 | D15: ='印刷・FAX 発注書'!I14 -> 156 | E15: ='入力 発注書'!Y14 -> 0 | F15: =$E15*C15 -> 0 | G15: =$E15*D15 -> 0
A16: ='入力 発注書'!A15 -> 3 | B16: ='入力 発注書'!B15 -> 新玉ねぎ | C16: ='印刷・FAX 発注書'!#REF! -> #REF! | D16: ='印刷・FAX 発注書'!#REF! -> #REF! | E16: ='入力 発注書'!Y15 -> 0 | F16: =$E16*C16 -> #REF! | G16: =$E16*D16 -> #REF!
A17: ='入力 発注書'!A16 -> 4 | B17: ='入力 発注書'!B16 -> 新玉ねぎ | C17: ='印刷・FAX 発注書'!H15 -> 158 | D17: ='印刷・FAX 発注書'!I15 -> 114 | E17: ='入力 発注書'!Y16 -> 0 | F17: =$E17*C17 -> 0 | G17: =$E17*D17 -> 0
A18: ='入力 発注書'!A17 -> 5 | B18: ='入力 発注書'!B17 -> 人参（冷蔵保存） | C18: ='印刷・FAX 発注書'!H16 -> 128 | D18: ='印刷・FAX 発注書'!I16 -> 93 | E18: ='入力 発注書'!Y17 -> 0 | F18: =$E18*C18 -> 0 | G18: =$E18*D18 -> 0
A19: ='入力 発注書'!A18 -> 6 | B19: ='入力 発注書'!B18 | C19: ='印刷・FAX 発注書'!H17 -> 0 | D19: ='印刷・FAX 発注書'!I17 -> 0 | E19: ='入力 発注書'!Y18 -> 0 | F19: =$E19*C19 -> 0 | G19: =$E19*D19 -> 0
A20: ='入力 発注書'!A19 -> 7 | B20: ='入力 発注書'!B19 -> じゃが芋 | C20: ='印刷・FAX 発注書'!H18 -> 128 | D20: ='印刷・FAX 発注書'!I18 -> 93 | E20: ='入力 発注書'!Y19 -> 0 | F20: =$E20*C20 -> 0 | G20: =$E20*D20 -> 0
A21: ='入力 発注書'!A20 -> 8 | B21: ='入力 発注書'!B20 -> 胡瓜 | C21: ='印刷・FAX 発注書'!H19 -> 138 | D21: ='印刷・FAX 発注書'!I19 -> 100 | E21: ='入力 発注書'!Y20 -> 0 | F21: =$E21*C21 -> 0 | G21: =$E21*D21 -> 0
A22: ='入力 発注書'!A21 -> 9 | B22: ='入力 発注書'!B21 -> トマト | C22: ='印刷・FAX 発注書'!H20 -> 238 | D22: ='印刷・FAX 発注書'!I20 -> 215 | E22: ='入力 発注書'!Y21 -> 0 | F22: =$E22*C22 -> 0 | G22: =$E22*D22 -> 0
A23: ='入力 発注書'!A22 -> 10 | B23: ='入力 発注書'!B22 -> レタス | C23: ='印刷・FAX 発注書'!H21 -> 258 | D23: ='印刷・FAX 発注書'!I21 -> 186 | E23: ='入力 発注書'!Y22 -> 0 | F23: =$E23*C23 -> 0 | G23: =$E23*D23 -> 0
A24: ='入力 発注書'!A23 -> 11 | B24: ='入力 発注書'!B23 -> ミニトマト | C24: ='印刷・FAX 発注書'!H22 -> 378 | D24: ='印刷・FAX 発注書'!I22 -> 287 | E24: ='入力 発注書'!Y23 -> 0 | F24: =$E24*C24 -> 0 | G24: =$E24*D24 -> 0
A25: ='入力 発注書'!A24 -> 12 | B25: ='入力 発注書'!B24 -> ネギ(１本） | C25: ='印刷・FAX 発注書'!H23 -> 108 | D25: ='印刷・FAX 発注書'!I23 -> 78 | E25: ='入力 発注書'!Y24 -> 0 | F25: =$E25*C25 -> 0 | G25: =$E25*D25 -> 0
A26: ='入力 発注書'!A25 -> 13 | B26: ='入力 発注書'!B25 -> ピーマン | C26: ='印刷・FAX 発注書'!H24 -> 198 | D26: ='印刷・FAX 発注書'!I24 -> 143 | E26: ='入力 発注書'!Y25 -> 0 | F26: =$E26*C26 -> 0 | G26: =$E26*D26 -> 0
A27: ='入力 発注書'!A26 -> 14 | B27: ='入力 発注書'!B26 -> キャベツ | C27: ='印刷・FAX 発注書'!H25 -> 138 | D27: ='印刷・FAX 発注書'!I25 -> 100 | E27: ='入力 発注書'!Y26 -> 0 | F27: =$E27*C27 -> 0 | G27: =$E27*D27 -> 0
A28: ='入力 発注書'!A27 -> 15 | B28: ='入力 発注書'!B27 -> キャベツ | C28: ='印刷・FAX 発注書'!H26 -> 358 | D28: ='印刷・FAX 発注書'!I26 -> 258 | E28: ='入力 発注書'!Y27 -> 0 | F28: =$E28*C28 -> 0 | G28: =$E28*D28 -> 0
... A70: ='入力 発注書'!A69 -> 57 | B70: ='入力 発注書'!B69 -> 0 | C70: ='印刷・FAX 発注書'!H68 -> 0 | D70: ='印刷・FAX 発注書'!I68 -> 0 | E70: ='入力 発注書'!Y69 -> 0 | F70: =$E70*C70 -> 0 | G70: =$E70*D70 -> 0
A71: ='入力 発注書'!A70 -> 58 | B71: ='入力 発注書'!B70 -> 送料 | D71: ='入力 発注書'!X70 -> 0 | E71: ='入力 発注書'!Y70 -> 0 | G71: =E71*D71 -> 0
B72: 合計(税込み) | D72: 8％対象 | F72: =SUM(F14:F70) -> #REF! | G72: =SUM(G14:G70) -> #REF!
D73: 10％対象 | G73: =G71 -> 0
B74: * 印は軽減税率8％対象商品となります。

Sheet B
G1: №
B2: 納 品 書 | C2: ='入力 発注書'!G8 -> 46224
D4: 仙台市太白区秋保湯元字寺田原45-11
D5: 有 限 会 社 マ ル カ
E6: TEL 022-398-2408
E7: FAX 022-397-2817
B8: ファミリーマート | C8: B店 様
B9: 下記のとおり納品いたしました
B11: 税込合計金額 ( 原価合計） | C11: =G72+G73 -> #REF! | F11: （消費税額等）
B12: 品 名 | C12: 単 価 | E12: 数 量 | F12: 金 額
C13: 売価 | D13: 原価 | F13: 売価 | G13: 原価
A14: ='入力 発注書'!A13 -> 1 | B14: ='入力 発注書'!B13 -> バナナ | C14: ='印刷・FAX 発注書'!H13 -> 98 | D14: ='印刷・FAX 発注書'!I13 -> 71 | E14: ='入力 発注書'!AA13 -> 0 | F14: =$E14*C14 -> 0 | G14: =$E14*D14 -> 0
A15: ='入力 発注書'!A14 -> 2 | B15: ='入力 発注書'!B14 -> バナナ | C15: ='印刷・FAX 発注書'!H14 -> 216 | D15: ='印刷・FAX 発注書'!I14 -> 156 | E15: ='入力 発注書'!AA14 -> 0 | F15: =$E15*C15 -> 0 | G15: =E15*D15 -> 0
A16: ='入力 発注書'!A15 -> 3 | B16: ='入力 発注書'!B15 -> 新玉ねぎ | C16: ='印刷・FAX 発注書'!#REF! -> #REF! | D16: ='印刷・FAX 発注書'!#REF! -> #REF! | E16: ='入力 発注書'!AA15 -> 0 | F16: =$E16*C16 -> #REF! | G16: =E16*D16 -> #REF!
A17: ='入力 発注書'!A16 -> 4 | B17: ='入力 発注書'!B16 -> 新玉ねぎ | C17: ='印刷・FAX 発注書'!H15 -> 158 | D17: ='印刷・FAX 発注書'!I15 -> 114 | E17: ='入力 発注書'!AA16 -> 0 | F17: =$E17*C17 -> 0 | G17: =E17*D17 -> 0
A18: ='入力 発注書'!A17 -> 5 | B18: ='入力 発注書'!B17 -> 人参（冷蔵保存） | C18: ='印刷・FAX 発注書'!H16 -> 128 | D18: ='印刷・FAX 発注書'!I16 -> 93 | E18: ='入力 発注書'!AA17 -> 0 | F18: =$E18*C18 -> 0 | G18: =E18*D18 -> 0
A19: ='入力 発注書'!A18 -> 6 | B19: ='入力 発注書'!B18 | C19: ='印刷・FAX 発注書'!H17 -> 0 | D19: ='印刷・FAX 発注書'!I17 -> 0 | E19: ='入力 発注書'!AA18 -> 0 | F19: =$E19*C19 -> 0 | G19: =E19*D19 -> 0
A20: ='入力 発注書'!A19 -> 7 | B20: ='入力 発注書'!B19 -> じゃが芋 | C20: ='印刷・FAX 発注書'!H18 -> 128 | D20: ='印刷・FAX 発注書'!I18 -> 93 | E20: ='入力 発注書'!AA19 -> 0 | F20: =$E20*C20 -> 0 | G20: =E20*D20 -> 0
A21: ='入力 発注書'!A20 -> 8 | B21: ='入力 発注書'!B20 -> 胡瓜 | C21: ='印刷・FAX 発注書'!H19 -> 138 | D21: ='印刷・FAX 発注書'!I19 -> 100 | E21: ='入力 発注書'!AA20 -> 0 | F21: =$E21*C21 -> 0 | G21: =E21*D21 -> 0
A22: ='入力 発注書'!A21 -> 9 | B22: ='入力 発注書'!B21 -> トマト | C22: ='印刷・FAX 発注書'!H20 -> 238 | D22: ='印刷・FAX 発注書'!I20 -> 215 | E22: ='入力 発注書'!AA21 -> 0 | F22: =$E22*C22 -> 0 | G22: =E22*D22 -> 0
A23: ='入力 発注書'!A22 -> 10 | B23: ='入力 発注書'!B22 -> レタス | C23: ='印刷・FAX 発注書'!H21 -> 258 | D23: ='印刷・FAX 発注書'!I21 -> 186 | E23: ='入力 発注書'!AA22 -> 0 | F23: =$E23*C23 -> 0 | G23: =E23*D23 -> 0
A24: ='入力 発注書'!A23 -> 11 | B24: ='入力 発注書'!B23 -> ミニトマト | C24: ='印刷・FAX 発注書'!H22 -> 378 | D24: ='印刷・FAX 発注書'!I22 -> 287 | E24: ='入力 発注書'!AA23 -> 0 | F24: =$E24*C24 -> 0 | G24: =E24*D24 -> 0
A25: ='入力 発注書'!A24 -> 12 | B25: ='入力 発注書'!B24 -> ネギ(１本） | C25: ='印刷・FAX 発注書'!H23 -> 108 | D25: ='印刷・FAX 発注書'!I23 -> 78 | E25: ='入力 発注書'!AA24 -> 0 | F25: =$E25*C25 -> 0 | G25: =E25*D25 -> 0
A26: ='入力 発注書'!A25 -> 13 | B26: ='入力 発注書'!B25 -> ピーマン | C26: ='印刷・FAX 発注書'!H24 -> 198 | D26: ='印刷・FAX 発注書'!I24 -> 143 | E26: ='入力 発注書'!AA25 -> 0 | F26: =$E26*C26 -> 0 | G26: =E26*D26 -> 0
A27: ='入力 発注書'!A26 -> 14 | B27: ='入力 発注書'!B26 -> キャベツ | C27: ='印刷・FAX 発注書'!H25 -> 138 | D27: ='印刷・FAX 発注書'!I25 -> 100 | E27: ='入力 発注書'!AA26 -> 0 | F27: =$E27*C27 -> 0 | G27: =E27*D27 -> 0
A28: ='入力 発注書'!A27 -> 15 | B28: ='入力 発注書'!B27 -> キャベツ | C28: ='印刷・FAX 発注書'!H26 -> 358 | D28: ='印刷・FAX 発注書'!I26 -> 258 | E28: ='入力 発注書'!AA27 -> 0 | F28: =$E28*C28 -> 0 | G28: =E28*D28 -> 0
A29: ='入力 発注書'!A28 -> 16 | B29: ='入力 発注書'!B28 -> 白菜1/2 | C29: ='印刷・FAX 発注書'!H27 -> 108 | D29: ='印刷・FAX 発注書'!I27 -> 78 | E29: ='入力 発注書'!AA28 -> 0 | F29: =$E29*C29 -> 0 | G29: =E29*D29 -> 0
A30: ='入力 発注書'!A29 -> 17 | B30: ='入力 発注書'!B29 -> 小松菜 | C30: ='印刷・FAX 発注書'!#REF! -> #REF! | D30: ='印刷・FAX 発注書'!#REF! -> #REF! | E30: ='入力 発注書'!AA29 -> 0 | F30: =$E30*C30 -> #REF! | G30: =E30*D30 -> #REF!
A31: ='入力 発注書'!A30 -> 18 | B31: ='入力 発注書'!B30 -> 大根1/2 | C31: ='印刷・FAX 発注書'!H28 -> 168 | D31: ='印刷・FAX 発注書'!I28 -> 121 | E31: ='入力 発注書'!AA30 -> 0 | F31: =$E31*C31 -> 0 | G31: =E31*D31 -> 0
A32: ='入力 発注書'!A31 -> 19 | B32: ='入力 発注書'!B31 -> ほうれん草 | C32: ='印刷・FAX 発注書'!H29 -> 148 | D32: ='印刷・FAX 発注書'!I29 -> 107 | E32: ='入力 発注書'!AA31 -> 0 | F32: =$E32*C32 -> 0 | G32: =E32*D32 -> 0
