Workbook

Sheet 入力　発注書
B8: ファミリーマート | D8: 46231 | Q8: 【集計】
B12: 品名 | C12: 賞味期限日数目安 | D12: 想定税込売価 | E12: 想定税込仕入額 | H12: 粗利益率 | I12: 大町２丁目 | N12: A | O12: B | Q12: 数量 | R12: 金額
A13: 1 | B13: バナナ | C13: 3 | D13: 218 | E13: =ROUNDUP(D13*G13,0) -> 164 | F13: 1 | G13: =F13-H13 -> 0.75 | H13: 0.25 | I13: 10 | N13: 0 | O13: 0 | Q13: =SUM(I13:P13) -> 10 | R13: =E13*Q13 -> 1640
A14: 2 | B14: バナナ | C14: 3 | D14: 93 | E14: =ROUNDUP(D14*G14,0) -> 70 | F14: 1 | G14: =F14-H14 -> 0.75 | H14: 0.25 | N14: 0 | O14: 0 | Q14: =SUM(I14:P14) -> 0 | R14: =E14*Q14 -> 0
A15: 3 | B15: 玉ねぎS | C15: 10 | D15: 138 | E15: =ROUNDUP(D15*G15,0) -> 104 | F15: 1 | G15: =F15-H15 -> 0.75 | H15: 0.25 | N15: 0 | O15: 0 | Q15: =SUM(I15:P15) -> 0 | R15: =E15*Q15 -> 0
A16: 4 | B16: 里芋 | C16: 10 | D16: 198 | E16: =ROUNDUP(D16*G16,0) -> 149 | F16: 1 | G16: =F16-H16 -> 0.75 | H16: 0.25 | N16: 0 | O16: 0 | Q16: =SUM(I16:P16) -> 0 | R16: =E16*Q16 -> 0
A17: 5 | B17: 人参 | C17: 5 | D17: 128 | E17: =ROUNDUP(D17*G17,0) -> 96 | F17: 1 | G17: =F17-H17 -> 0.75 | H17: 0.25 | I17: 5 | N17: 0 | O17: 0 | Q17: =SUM(I17:P17) -> 5 | R17: =E17*Q17 -> 480
A18: 6 | B18: じゃが芋 | C18: 7 | D18: 128 | E18: =ROUNDUP(D18*G18,0) -> 96 | F18: 1 | G18: =F18-H18 -> 0.75 | H18: 0.25 | N18: 0 | O18: 0 | Q18: =SUM(I18:P18) -> 0 | R18: =E18*Q18 -> 0
A19: 7 | B19: 胡瓜2本 | C19: 5 | D19: 138 | E19: =ROUNDUP(D19*G19,0) -> 104 | F19: 1 | G19: =F19-H19 -> 0.75 | H19: 0.25 | I19: 5 | N19: 0 | O19: 0 | Q19: =SUM(I19:P19) -> 5 | R19: =E19*Q19 -> 520
A20: 8 | B20: トマト | C20: 5 | D20: 288 | E20: =ROUNDUP(D20*G20,0) -> 216 | F20: 1 | G20: =F20-H20 -> 0.75 | H20: 0.25 | I20: 3 | N20: 0 | O20: 0 | Q20: =SUM(I20:P20) -> 3 | R20: =E20*Q20 -> 648
A21: 9 | B21: フルーツトマト | C21: 7 | D21: 238 | E21: =ROUNDUP(D21*G21,0) -> 179 | F21: 1 | G21: =F21-H21 -> 0.75 | H21: 0.25 | N21: 0 | O21: 0 | Q21: =SUM(I21:P21) -> 0 | R21: =E21*Q21 -> 0
A22: 10 | B22: ミニトマト | C22: 7 | D22: 298 | E22: =ROUNDUP(D22*G22,0) -> 224 | F22: 1 | G22: =F22-H22 -> 0.75 | H22: 0.25 | I22: 3 | N22: 0 | O22: 0 | Q22: =SUM(I22:P22) -> 3 | R22: =E22*Q22 -> 672
A23: 11 | B23: ネギ1束 | C23: 7 | D23: 198 | E23: =ROUNDUP(D23*G23,0) -> 149 | F23: 1 | G23: =F23-H23 -> 0.75 | H23: 0.25 | N23: 0 | O23: 0 | Q23: =SUM(I23:P23) -> 0 | R23: =E23*Q23 -> 0
A24: 12 | B24: ピーマン | C24: 5 | D24: 198 | E24: =ROUNDUP(D24*G24,0) -> 149 | F24: 1 | G24: =F24-H24 -> 0.75 | H24: 0.25 | N24: 0 | O24: 0 | Q24: =SUM(I24:P24) -> 0 | R24: =E24*Q24 -> 0
A25: 13 | B25: キャベツ1個 | C25: 5 | D25: 248 | E25: =ROUNDUP(D25*G25,0) -> 186 | F25: 1 | G25: =F25-H25 -> 0.75 | H25: 0.25 | N25: 0 | O25: 0 | Q25: =SUM(I25:P25) -> 0 | R25: =E25*Q25 -> 0
A26: 14 | B26: サニーレタス | C26: 4 | D26: 98 | E26: =ROUNDUP(D26*G26,0) -> 74 | F26: 1 | G26: =F26-H26 -> 0.75 | H26: 0.25 | N26: 0 | O26: 0 | Q26: =SUM(I26:P26) -> 0 | R26: =E26*Q26 -> 0
A27: 15 | B27: 白菜1/2個 | C27: 3 | D27: 248 | E27: =ROUNDUP(D27*G27,0) -> 186 | F27: 1 | G27: =F27-H27 -> 0.75 | H27: 0.25 | N27: 0 | O27: 0 | Q27: =SUM(I27:P27) -> 0 | R27: =E27*Q27 -> 0
A28: 16 | B28: 大根1本 | C28: 4 | D28: 128 | E28: =ROUNDUP(D28*G28,0) -> 96 | F28: 1 | G28: =F28-H28 -> 0.75 | H28: 0.25 | I28: 5 | N28: 0 | O28: 0 | Q28: =SUM(I28:P28) -> 5 | R28: =E28*Q28 -> 480
A29: 17 | B29: 小松菜 | C29: 5 | D29: 158 | E29: =ROUNDUP(D29*G29,0) -> 119 | F29: 1 | G29: =F29-H29 -> 0.75 | H29: 0.25 | N29: 0 | O29: 0 | Q29: =SUM(I29:P29) -> 0 | R29: =E29*Q29 -> 0
A30: 18 | B30: レタス | C30: 5 | D30: 198 | E30: =ROUNDUP(D30*G30,0) -> 149 | F30: 1 | G30: =F30-H30 -> 0.75 | H30: 0.25 | N30: 0 | O30: 0 | Q30: =SUM(I30:P30) -> 0 | R30: =E30*Q30 -> 0
A31: 19 | B31: チンゲン菜 | C31: 5 | D31: 98 | E31: =ROUNDUP(D31*G31,0) -> 74 | F31: 1 | G31: =F31-H31 -> 0.75 | H31: 0.25 | N31: 0 | O31: 0 | Q31: =SUM(I31:P31) -> 0 | R31: =E31*Q31 -> 0
A32: 20 | B32: 豆苗 | C32: 6 | D32: 138 | E32: =ROUNDUP(D32*G32,0) -> 104 | F32: 1 | G32: =F32-H32 -> 0.75 | H32: 0.25 | I32: 3 | N32: 0 | O32: 0 | Q32: =SUM(I32:P32) -> 3 | R32: =E32*Q32 -> 312
A33: 21 | B33: 茄子2本 | C33: 5 | D33: 178 | E33: =ROUNDUP(D33*G33,0) -> 134 | F33: 1 | G33: =F33-H33 -> 0.75 | H33: 0.25 | N33: 0 | O33: 0 | Q33: =SUM(I33:P33) -> 0 | R33: =E33*Q33 -> 0
A34: 22 | B34: 国産生姜 | C34: 7 | D34: 238 | E34: =ROUNDUP(D34*G34,0) -> 179 | F34: 1 | G34: =F34-H34 -> 0.75 | H34: 0.25 | N34: 0 | O34: 0 | Q34: =SUM(I34:P34) -> 0 | R34: =E34*Q34 -> 0
A35: 23 | B35: ごぼう | C35: 5 | D35: 248 | E35: =ROUNDUP(D35*G35,0) -> 186 | F35: 1 | G35: =F35-H35 -> 0.75 | H35: 0.25 | N35: 0 | O35: 0 | Q35: =SUM(I35:P35) -> 0 | R35: =E35*Q35 -> 0
A36: 24 | B36: さつま芋 | C36: 10 | D36: 198 | E36: =ROUNDUP(D36*G36,0) -> 149 | F36: 1 | G36: =F36-H36 -> 0.75 | H36: 0.25 | N36: 0 | O36: 0 | Q36: =SUM(I36:P36) -> 0 | R36: =E36*Q36 -> 0
A37: 25 | B37: ほうれん草 | C37: 10 | D37: 198 | E37: =ROUNDUP(D37*G37,0) -> 149 | F37: 1 | G37: =F37-H37 -> 0.75 | H37: 0.25 | N37: 0 | O37: 0 | Q37: =SUM(I37:P37) -> 0 | R37: =E37*Q37 -> 0
A38: 26 | B38: えのき茸 | C38: 5 | D38: 148 | E38: =ROUNDUP(D38*G38,0) -> 111 | F38: 1 | G38: =F38-H38 -> 0.75 | H38: 0.25 | N38: 0 | O38: 0 | Q38: =SUM(I38:P38) -> 0 | R38: =E38*Q38 -> 0
A39: 27 | B39: しめじ | C39: 5 | D39: 148 | E39: =ROUNDUP(D39*G39,0) -> 111 | F39: 1 | G39: =F39-H39 -> 0.75 | H39: 0.25 | N39: 0 | O39: 0 | Q39: =SUM(I39:P39) -> 0 | R39: =E39*Q39 -> 0
A40: 28 | B40: しいたけ | C40: 4 | D40: 178 | E40: =ROUNDUP(D40*G40,0) -> 134 | F40: 1 | G40: =F40-H40 -> 0.75 | H40: 0.25 | N40: 0 | O40: 0 | Q40: =SUM(I40:P40) -> 0 | R40: =E40*Q40 -> 0
A41: 29 | B41: まいたけ | C41: 5 | D41: 168 | E41: =ROUNDUP(D41*G41,0) -> 126 | F41: 1 | G41: =F41-H41 -> 0.75 | H41: 0.25 | N41: 0 | O41: 0 | Q41: =SUM(I41:P41) -> 0 | R41: =E41*Q41 -> 0
A42: 30 | B42: エリンギ | C42: 5 | D42: 168 | E42: =ROUNDUP(D42*G42,0) -> 126 | F42: 1 | G42: =F42-H42 -> 0.75 | H42: 0.25 | N42: 0 | O42: 0 | Q42: =SUM(I42:P42) -> 0 | R42: =E42*Q42 -> 0
A43: 31 | B43: なめこ | C43: 5 | D43: 108 | E43: =ROUNDUP(D43*G43,0) -> 81 | F43: 1 | G43: =F43-H43 -> 0.75 | H43: 0.25 | I43: 3 | N43: 0 | O43: 0 | Q43: =SUM(I43:P43) -> 3 | R43: =E43*Q43 -> 243
A44: 32 | B44: にら | C44: 5 | D44: 98 | E44: =ROUNDUP(D44*G44,0) -> 74 | F44: 1 | G44: =F44-H44 -> 0.75 | H44: 0.25 | I44: 5 | N44: 0 | O44: 0 | Q44: =SUM(I44:P44) -> 5 | R44: =E44*Q44 -> 370
A45: 33 | B45: レモン | C45: 15 | D45: 128 | E45: =ROUNDUP(D45*G45,0) -> 96 | F45: 1 | G45: =F45-H45 -> 0.75 | H45: 0.25 | N45: 0 | O45: 0 | Q45: =SUM(I45:P45) -> 0 | R45: =E45*Q45 -> 0
A46: 34 | B46: 中国ニンニク | C46: 5 | D46: 168 | E46: =ROUNDUP(D46*G46,0) -> 126 | F46: 1 | G46: =F46-H46 -> 0.75 | H46: 0.25 | N46: 0 | O46: 0 | Q46: =SUM(I46:P46) -> 0 | R46: =E46*Q46 -> 0
A47: 35 | B47: みょうが | C47: 5 | D47: 198 | E47: =ROUNDUP(D47*G47,0) -> 149 | F47: 1 | G47: =F47-H47 -> 0.75 | H47: 0.25 | N47: 0 | O47: 0 | Q47: =SUM(I47:P47) -> 0 | R47: =E47*Q47 -> 0
A48: 36 | B48: 大葉しそ | C48: 4 | D48: 138 | E48: =ROUNDUP(D48*G48,0) -> 104 | F48: 1 | G48: =F48-H48 -> 0.75 | H48: 0.25 | N48: 0 | O48: 0 | Q48: =SUM(I48:P48) -> 0 | R48: =E48*Q48 -> 0
A49: 37 | B49: リンゴ | C49: 5 | D49: 538 | E49: =ROUNDUP(D49*G49,0) -> 404 | F49: 1 | G49: =F49-H49 -> 0.75 | H49: 0.25 | N49: 0 | O49: 0 | Q49: =SUM(I49:P49) -> 0 | R49: =E49*Q49 -> 0
A50: 38 | B50: とうもろこし | C50: 7 | D50: 128 | E50: =ROUNDUP(D50*G50,0) -> 96 | F50: 1 | G50: =F50-H50 -> 0.75 | H50: 0.25 | I50: 10 | N50: 0 | O50: 0 | Q50: =SUM(I50:P50) -> 10 | R50: =E50*Q50 -> 960
...

Sheet 大町２丁目
G1: №
B2: 納 品 書 | C2: ='入力 発注書'!D8 -> 46231
D4: 仙台市太白区秋保湯元字寺田原45-11
D5: 有 限 会 社 マ ル カ
E6: TEL 022-398-2408
E7: FAX 022-397-2817
B8: ファミリーマート | C8: 大町２丁目店
B9: 下記のとおり納品いたしました
B11: 税込合計金額 ( 原価合計） | C11: =G72+G73 -> 15841 | F11: （消費税額等）
B12: 品 名 | C12: 単 価 | E12: 数 量 | F12: 金 額
C13: 売価 | D13: 原価 | F13: 売価 | G13: 原価
A14: ='入力 発注書'!A13 -> 1 | B14: ='入力 発注書'!B13 -> バナナ | C14: ='入力 発注書'!D13 -> 218 | D14: ='入力 発注書'!E13 -> 164 | E14: ='入力 発注書'!I13 -> 10 | F14: =$E14*C14 -> 2180 | G14: =$E14*D14 -> 1640
A15: ='入力 発注書'!A14 -> 2 | B15: ='入力 発注書'!B14 -> バナナ | C15: ='入力 発注書'!D14 -> 93 | D15: ='入力 発注書'!E14 -> 70 | E15: ='入力 発注書'!I14 -> 0 | F15: =$E15*C15 -> 0 | G15: =E15*D15 -> 0
A16: ='入力 発注書'!A15 -> 3 | B16: ='入力 発注書'!B15 -> 玉ねぎS | C16: ='入力 発注書'!D15 -> 138 | D16: ='入力 発注書'!E15 -> 104 | E16: ='入力 発注書'!I15 -> 0 | F16: =$E16*C16 -> 0 | G16: =E16*D16 -> 0
A17: ='入力 発注書'!A16 -> 4 | B17: ='入力 発注書'!B16 -> 里芋 | C17: ='入力 発注書'!D16 -> 198 | D17: ='入力 発注書'!E16 -> 149 | E17: ='入力 発注書'!I16 -> 0 | F17: =$E17*C17 -> 0 | G17: =E17*D17 -> 0
A18: ='入力 発注書'!A17 -> 5 | B18: ='入力 発注書'!B17 -> 人参 | C18: ='入力 発注書'!D17 -> 128 | D18: ='入力 発注書'!E17 -> 96 | E18: ='入力 発注書'!I17 -> 5 | F18: =$E18*C18 -> 640 | G18: =E18*D18 -> 480
A19: ='入力 発注書'!A18 -> 6 | B19: ='入力 発注書'!B18 -> じゃが芋 | C19: ='入力 発注書'!D18 -> 128 | D19: ='入力 発注書'!E18 -> 96 | E19: ='入力 発注書'!I18 -> 0 | F19: =$E19*C19 -> 0 | G19: =E19*D19 -> 0
A20: ='入力 発注書'!A19 -> 7 | B20: ='入力 発注書'!B19 -> 胡瓜2本 | C20: ='入力 発注書'!D19 -> 138 | D20: ='入力 発注書'!E19 -> 104 | E20: ='入力 発注書'!I19 -> 5 | F20: =$E20*C20 -> 690 | G20: =E20*D20 -> 520
A21: ='入力 発注書'!A20 -> 8 | B21: ='入力 発注書'!B20 -> トマト | C21: ='入力 発注書'!D20 -> 288 | D21: ='入力 発注書'!E20 -> 216 | E21: ='入力 発注書'!I20 -> 3 | F21: =$E21*C21 -> 864 | G21: =E21*D21 -> 648
A22: ='入力 発注書'!A21 -> 9 | B22: ='入力 発注書'!B21 -> フルーツトマト | C22: ='入力 発注書'!D21 -> 238 | D22: ='入力 発注書'!E21 -> 179 | E22: ='入力 発注書'!I21 -> 0 | F22: =$E22*C22 -> 0 | G22: =E22*D22 -> 0
A23: ='入力 発注書'!A22 -> 10 | B23: ='入力 発注書'!B22 -> ミニトマト | C23: ='入力 発注書'!D22 -> 298 | D23: ='入力 発注書'!E22 -> 224 | E23: ='入力 発注書'!I22 -> 3 | F23: =$E23*C23 -> 894 | G23: =E23*D23 -> 672
A24: ='入力 発注書'!A23 -> 11 | B24: ='入力 発注書'!B23 -> ネギ1束 | C24: ='入力 発注書'!D23 -> 198 | D24: ='入力 発注書'!E23 -> 149 | E24: ='入力 発注書'!I23 -> 0 | F24: =$E24*C24 -> 0 | G24: =E24*D24 -> 0
A25: ='入力 発注書'!A24 -> 12 | B25: ='入力 発注書'!B24 -> ピーマン | C25: ='入力 発注書'!D24 -> 198 | D25: ='入力 発注書'!E24 -> 149 | E25: ='入力 発注書'!I24 -> 0 | F25: =$E25*C25 -> 0 | G25: =E25*D25 -> 0
A26: ='入力 発注書'!A25 -> 13 | B26: ='入力 発注書'!B25 -> キャベツ1個 | C26: ='入力 発注書'!D25 -> 248 | D26: ='入力 発注書'!E25 -> 186 | E26: ='入力 発注書'!I25 -> 0 | F26: =$E26*C26 -> 0 | G26: =E26*D26 -> 0
... A70: ='入力 発注書'!A69 -> 57 | B70: ='入力 発注書'!B69 -> 切り干し大根 | C70: ='入力 発注書'!D69 -> 238 | D70: ='入力 発注書'!E69 -> 179 | E70: ='入力 発注書'!I69 -> 0 | F70: =$E70*C70 -> 0 | G70: =E70*D70 -> 0
A71: ='入力 発注書'!A70 -> 58 | B71: ='入力 発注書'!B70 -> 送料 | D71: ='入力 発注書'!I70 -> 550 | E71: =IF(D71<>0,1,0) -> 1 | G71: =E71*D71 -> 550
B72: 合計(税込み) | D72: 8％対象 | F72: =SUM(F14:F70) -> 20368 | G72: =SUM(G14:G70) -> 15291
D73: 10％対象 | G73: =G71 -> 550
B74: * 印は軽減税率8％対象商品となります。

Sheet 八乙女中央
G1: №
B2: 納 品 書 | C2: ='入力 発注書'!D8 -> 46231
D4: 仙台市太白区秋保湯元字寺田原45-11
D5: 有 限 会 社 マ ル カ
E6: TEL 022-398-2408
E7: FAX 022-397-2817
B8: ファミリーマート | C8: 八乙女中央店 様
B9: 下記のとおり納品いたしました
B11: 税込合計金額 ( 原価合計） | C11: =G72+G73 -> 0 | F11: （消費税額等）
B12: 品 名 | C12: 単 価 | E12: 数 量 | F12: 金 額
C13: 売価 | D13: 原価 | F13: 売価 | G13: 原価
A14: ='入力 発注書'!A13 -> 1 | B14: ='入力 発注書'!B13 -> バナナ | C14: ='入力 発注書'!D13 -> 218 | D14: ='入力 発注書'!E13 -> 164 | E14: ='入力 発注書'!J13 -> 0 | F14: =$E14*C14 -> 0 | G14: =$E14*D14 -> 0
A15: ='入力 発注書'!A14 -> 2 | B15: ='入力 発注書'!B14 -> バナナ | C15: ='入力 発注書'!D14 -> 93 | D15: ='入力 発注書'!E14 -> 70 | E15: ='入力 発注書'!J14 -> 0 | F15: =$E15*C15 -> 0 | G15: =E15*D15 -> 0
A16: ='入力 発注書'!A15 -> 3 | B16: ='入力 発注書'!B15 -> 玉ねぎS | C16: ='入力 発注書'!D15 -> 138 | D16: ='入力 発注書'!E15 -> 104 | E16: ='入力 発注書'!J15 -> 0 | F16: =$E16*C16 -> 0 | G16: =E16*D16 -> 0
A17: ='入力 発注書'!A16 -> 4 | B17: ='入力 発注書'!B16 -> 里芋 | C17: ='入力 発注書'!D16 -> 198 | D17: ='入力 発注書'!E16 -> 149 | E17: ='入力 発注書'!J16 -> 0 | F17: =$E17*C17 -> 0 | G17: =E17*D17 -> 0
A18: ='入力 発注書'!A17 -> 5 | B18: ='入力 発注書'!B17 -> 人参 | C18: ='入力 発注書'!D17 -> 128 | D18: ='入力 発注書'!E17 -> 96 | E18: ='入力 発注書'!J17 -> 0 | F18: =$E18*C18 -> 0 | G18: =E18*D18 -> 0
A19: ='入力 発注書'!A18 -> 6 | B19: ='入力 発注書'!B18 -> じゃが芋 | C19: ='入力 発注書'!D18 -> 128 | D19: ='入力 発注書'!E18 -> 96 | E19: ='入力 発注書'!J18 -> 0 | F19: =$E19*C19 -> 0 | G19: =E19*D19 -> 0
A20: ='入力 発注書'!A19 -> 7 | B20: ='入力 発注書'!B19 -> 胡瓜2本 | C20: ='入力 発注書'!D19 -> 138 | D20: ='入力 発注書'!E19 -> 104 | E20: ='入力 発注書'!J19 -> 0 | F20: =$E20*C20 -> 0 | G20: =E20*D20 -> 0
A21: ='入力 発注書'!A20 -> 8 | B21: ='入力 発注書'!B20 -> トマト | C21: ='入力 発注書'!D20 -> 288 | D21: ='入力 発注書'!E20 -> 216 | E21: ='入力 発注書'!J20 -> 0 | F21: =$E21*C21 -> 0 | G21: =E21*D21 -> 0
A22: ='入力 発注書'!A21 -> 9 | B22: ='入力 発注書'!B21 -> フルーツトマト | C22: ='入力 発注書'!D21 -> 238 | D22: ='入力 発注書'!E21 -> 179 | E22: ='入力 発注書'!J21 -> 0 | F22: =$E22*C22 -> 0 | G22: =E22*D22 -> 0
A23: ='入力 発注書'!A22 -> 10 | B23: ='入力 発注書'!B22 -> ミニトマト | C23: ='入力 発注書'!D22 -> 298 | D23: ='入力 発注書'!E22 -> 224 | E23: ='入力 発注書'!J22 -> 0 | F23: =$E23*C23 -> 0 | G23: =E23*D23 -> 0
A24: ='入力 発注書'!A23 -> 11 | B24: ='入力 発注書'!B23 -> ネギ1束 | C24: ='入力 発注書'!D23 -> 198 | D24: ='入力 発注書'!E23 -> 149 | E24: ='入力 発注書'!J23 -> 0 | F24: =$E24*C24 -> 0 | G24: =E24*D24 -> 0
A25: ='入力 発注書'!A24 -> 12 | B25: ='入力 発注書'!B24 -> ピーマン | C25: ='入力 発注書'!D24 -> 198 | D25: ='入力 発注書'!E24 -> 149 | E25: ='入力 発注書'!J24 -> 0 | F25: =$E25*C25 -> 0 | G25: =E25*D25 -> 0
A26: ='入力 発注書'!A25 -> 13 | B26: ='入力 発注書'!B25 -> キャベツ1個 | C26: ='入力 発注書'!D25 -> 248 | D26: ='入力 発注書'!E25 -> 186 | E26: ='入力 発注書'!J25 -> 0 | F26: =$E26*C26 -> 0 | G26: =E26*D26 -> 0
... A70: ='入力 発注書'!A69 -> 57 | B70: ='入力 発注書'!B69 -> 切り干し大根 | C70: ='入力 発注書'!D69 -> 238 | D70: ='入力 発注書'!E69 -> 179 | E70: ='入力 発注書'!J69 -> 0 | F70: =$E70*C70 -> 0 | G70: =E70*D70 -> 0
A71: ='入力 発注書'!A70 -> 58 | B71: ='入力 発注書'!B70 -> 送料 | D71: ='入力 発注書'!J70 -> 0 | E71: =IF(D71<>0,1,0) -> 0 | G71: =E71*D71 -> 0
B72: 合計(税込み) | D72: 8％対象 | F72: =SUM(F14:F70) -> 0 | G72: =SUM(G14:G70) -> 0
D73: 10％対象 | G73: =G71 -> 0
B74: * 印は軽減税率8％対象商品となります。

Sheet 川平1丁目
G1: №
B2: 納 品 書 | C2: ='入力 発注書'!D8 -> 46231
D4: 仙台市太白区秋保湯元字寺田原45-11
D5: 有 限 会 社 マ ル カ
E6: TEL 022-398-2408
E7: FAX 022-397-2817
B8: ファミリーマート | C8: 川平1丁目店 様
B9: 下記のとおり納品いたしました
B11: 税込合計金額 ( 原価合計） | C11: =G72+G73 -> 0 | F11: （消費税額等）
B12: 品 名 | C12: 単 価 | E12: 数 量 | F12: 金 額
C13: 売価 | D13: 原価 | F13: 売価 | G13: 原価
A14: ='入力 発注書'!A13 -> 1 | B14: ='入力 発注書'!B13 -> バナナ | C14: ='入力 発注書'!D13 -> 218 | D14: ='入力 発注書'!E13 -> 164 | E14: ='入力 発注書'!K13 -> 0 | F14: =$E14*C14 -> 0 | G14: =$E14*D14 -> 0
A15: ='入力 発注書'!A14 -> 2 | B15: ='入力 発注書'!B14 -> バナナ | C15: ='入力 発注書'!D14 -> 93 | D15: ='入力 発注書'!E14 -> 70 | E15: ='入力 発注書'!K14 -> 0 | F15: =$E15*C15 -> 0 | G15: =E15*D15 -> 0
A16: ='入力 発注書'!A15 -> 3 | B16: ='入力 発注書'!B15 -> 玉ねぎS | C16: ='入力 発注書'!D15 -> 138 | D16: ='入力 発注書'!E15 -> 104 | E16: ='入力 発注書'!K15 -> 0 | F16: =$E16*C16 -> 0 | G16: =E16*D16 -> 0
A17: ='入力 発注書'!A16 -> 4 | B17: ='入力 発注書'!B16 -> 里芋 | C17: ='入力 発注書'!D16 -> 198 | D17: ='入力 発注書'!E16 -> 149 | E17: ='入力 発注書'!K16 -> 0 | F17: =$E17*C17 -> 0 | G17: =E17*D17 -> 0
A18: ='入力 発注書'!A17 -> 5 | B18: ='入力 発注書'!B17 -> 人参 | C18: ='入力 発注書'!D17 -> 128 | D18: ='入力 発注書'!E17 -> 96 | E18: ='入力 発注書'!K17 -> 0 | F18: =$E18*C18 -> 0 | G18: =E18*D18 -> 0
A19: ='入力 発注書'!A18 -> 6 | B19: ='入力 発注書'!B18 -> じゃが芋 | C19: ='入力 発注書'!D18 -> 128 | D19: ='入力 発注書'!E18 -> 96 | E19: ='入力 発注書'!K18 -> 0 | F19: =$E19*C19 -> 0 | G19: =E19*D19 -> 0
A20: ='入力 発注書'!A19 -> 7 | B20: ='入力 発注書'!B19 -> 胡瓜2本 | C20: ='入力 発注書'!D19 -> 138 | D20: ='入力 発注書'!E19 -> 104 | E20: ='入力 発注書'!K19 -> 0 | F20: =$E20*C20 -> 0 | G20: =E20*D20 -> 0
A21: ='入力 発注書'!A20 -> 8 | B21: ='入力 発注書'!B20 -> トマト | C21: ='入力 発注書'!D20 -> 288 | D21: ='入力 発注書'!E20 -> 216 | E21: ='入力 発注書'!K20 -> 0 | F21: =$E21*C21 -> 0 | G21: =E21*D21 -> 0
A22: ='入力 発注書'!A21 -> 9 | B22: ='入力 発注書'!B21 -> フルーツトマト | C22: ='入力 発注書'!D21 -> 238 | D22: ='入力 発注書'!E21 -> 179 | E22: ='入力 発注書'!K21 -> 0 | F22: =$E22*C22 -> 0 | G22: =E22*D22 -> 0
A23: ='入力 発注書'!A22 -> 10 | B23: ='入力 発注書'!B22 -> ミニトマト | C23: ='入力 発注書'!D22 -> 298 | D23: ='入力 発注書'!E22 -> 224 | E23: ='入力 発注書'!K22 -> 0 | F23: =$E23*C23 -> 0 | G23: =E23*D23 -> 0
A24: ='入力 発注書'!A23 -> 11 | B24: ='入力 発注書'!B23 -> ネギ1束 | C24: ='入力 発注書'!D23 -> 198 | D24: ='入力 発注書'!E23 -> 149 | E24: ='入力 発注書'!K23 -> 0 | F24: =$E24*C24 -> 0 | G24: =E24*D24 -> 0
A25: ='入力 発注書'!A24 -> 12 | B25: ='入力 発注書'!B24 -> ピーマン | C25: ='入力 発注書'!D24 -> 198 | D25: ='入力 発注書'!E24 -> 149 | E25: ='入力 発注書'!K24 -> 0 | F25: =$E25*C25 -> 0 | G25: =E25*D25 -> 0
A26: ='入力 発注書'!A25 -> 13 | B26: ='入力 発注書'!B25 -> キャベツ1個 | C26: ='入力 発注書'!D25 -> 248 | D26: ='入力 発注書'!E25 -> 186 | E26: ='入力 発注書'!K25 -> 0 | F26: =$E26*C26 -> 0 | G26: =E26*D26 -> 0
... A70: ='入力 発注書'!A69 -> 57 | B70: ='入力 発注書'!B69 -> 切り干し大根 | C70: ='入力 発注書'!D69 -> 238 | D70: ='入力 発注書'!E69 -> 179 | E70: ='入力 発注書'!K69 -> 0 | F70: =$E70*C70 -> 0 | G70: =E70*D70 -> 0
A71: ='入力 発注書'!A70 -> 58 | B71: ='入力 発注書'!B70 -> 送料 | D71: ='入力 発注書'!K70 -> 0 | E71: =IF(D71<>0,1,0) -> 0 | G71: =E71*D71 -> 0
B72: 合計(税込み) | D72: 8％対象 | F72: =SUM(F14:F70) -> 0 | G72: =SUM(G14:G70) -> 0
D73: 10％対象 | G73: =G71 -> 0
B74: * 印は軽減税率8％対象商品となります。

Sheet 堤町
G1: №
B2: 納 品 書 | C2: ='入力 発注書'!D8 -> 46231
D4: 仙台市太白区秋保湯元字寺田原45-11
D5: 有 限 会 社 マ ル カ
E6: TEL 022-398-2408
E7: FAX 022-397-2817
B8: ファミリーマート | C8: 堤町店 様
B9: 下記のとおり納品いたしました
B11: 税込合計金額 ( 原価合計） | C11: =G72+G73 -> 0 | F11: （消費税額等）
B12: 品 名 | C12: 単 価 | E12: 数 量 | F12: 金 額
C13: 売価 | D13: 原価 | F13: 売価 | G13: 原価
A14: ='入力 発注書'!A13 -> 1 | B14: ='入力 発注書'!B13 -> バナナ | C14: ='入力 発注書'!D13 -> 218 | D14: ='入力 発注書'!E13 -> 164 | E14: ='入力 発注書'!L13 -> 0 | F14: =$E14*C14 -> 0 | G14: =$E14*D14 -> 0
A15: ='入力 発注書'!A14 -> 2 | B15: ='入力 発注書'!B14 -> バナナ | C15: ='入力 発注書'!D14 -> 93 | D15: ='入力 発注書'!E14 -> 70 | E15: ='入力 発注書'!L14 -> 0 | F15: =$E15*C15 -> 0 | G15: =E15*D15 -> 0
A16: ='入力 発注書'!A15 -> 3 | B16: ='入力 発注書'!B15 -> 玉ねぎS | C16: ='入力 発注書'!D15 -> 138 | D16: ='入力 発注書'!E15 -> 104 | E16: ='入力 発注書'!L15 -> 0 | F16: =$E16*C16 -> 0 | G16: =E16*D16 -> 0
A17: ='入力 発注書'!A16 -> 4 | B17: ='入力 発注書'!B16 -> 里芋 | C17: ='入力 発注書'!D16 -> 198 | D17: ='入力 発注書'!E16 -> 149 | E17: ='入力 発注書'!L16 -> 0 | F17: =$E17*C17 -> 0 | G17: =E17*D17 -> 0
A18: ='入力 発注書'!A17 -> 5 | B18: ='入力 発注書'!B17 -> 人参 | C18: ='入力 発注書'!D17 -> 128 | D18: ='入力 発注書'!E17 -> 96 | E18: ='入力 発注書'!L17 -> 0 | F18: =$E18*C18 -> 0 | G18: =E18*D18 -> 0
A19: ='入力 発注書'!A18 -> 6 | B19: ='入力 発注書'!B18 -> じゃが芋 | C19: ='入力 発注書'!D18 -> 128 | D19: ='入力 発注書'!E18 -> 96 | E19: ='入力 発注書'!L18 -> 0 | F19: =$E19*C19 -> 0 | G19: =E19*D19 -> 0
A20: ='入力 発注書'!A19 -> 7 | B20: ='入力 発注書'!B19 -> 胡瓜2本 | C20: ='入力 発注書'!D19 -> 138 | D20: ='入力 発注書'!E19 -> 104 | E20: ='入力 発注書'!L19 -> 0 | F20: =$E20*C20 -> 0 | G20: =E20*D20 -> 0
A21: ='入力 発注書'!A20 -> 8 | B21: ='入力 発注書'!B20 -> トマト | C21: ='入力 発注書'!D20 -> 288 | D21: ='入力 発注書'!E20 -> 216 | E21: ='入力 発注書'!L20 -> 0 | F21: =$E21*C21 -> 0 | G21: =E21*D21 -> 0
A22: ='入力 発注書'!A21 -> 9 | B22: ='入力 発注書'!B21 -> フルーツトマト | C22: ='入力 発注書'!D21 -> 238 | D22: ='入力 発注書'!E21 -> 179 | E22: ='入力 発注書'!L21 -> 0 | F22: =$E22*C22 -> 0 | G22: =E22*D22 -> 0
A23: ='入力 発注書'!A22 -> 10 | B23: ='入力 発注書'!B22 -> ミニトマト | C23: ='入力 発注書'!D22 -> 298 | D23: ='入力 発注書'!E22 -> 224 | E23: ='入力 発注書'!L22 -> 0 | F23: =$E23*C23 -> 0 | G23: =E23*D23 -> 0
A24: ='入力 発注書'!A23 -> 11 | B24: ='入力 発注書'!B23 -> ネギ1束 | C24: ='入力 発注書'!D23 -> 198 | D24: ='入力 発注書'!E23 -> 149 | E24: ='入力 発注書'!L23 -> 0 | F24: =$E24*C24 -> 0 | G24: =E24*D24 -> 0
A25: ='入力 発注書'!A24 -> 12 | B25: ='入力 発注書'!B24 -> ピーマン | C25: ='入力 発注書'!D24 -> 198 | D25: ='入力 発注書'!E24 -> 149 | E25: ='入力 発注書'!L24 -> 0 | F25: =$E25*C25 -> 0 | G25: =E25*D25 -> 0
A26: ='入力 発注書'!A25 -> 13 | B26: ='入力 発注書'!B25 -> キャベツ1個 | C26: ='入力 発注書'!D25 -> 248 | D26: ='入力 発注書'!E25 -> 186 | E26: ='入力 発注書'!L25 -> 0 | F26: =$E26*C26 -> 0 | G26: =E26*D26 -> 0
... A70: ='入力 発注書'!A69 -> 57 | B70: ='入力 発注書'!B69 -> 切り干し大根 | C70: ='入力 発注書'!D69 -> 238 | D70: ='入力 発注書'!E69 -> 179 | E70: ='入力 発注書'!L69 -> 0 | F70: =$E70*C70 -> 0 | G70: =E70*D70 -> 0
A71: ='入力 発注書'!A70 -> 58 | B71: ='入力 発注書'!B70 -> 送料 | D71: ='入力 発注書'!L70 -> 0 | E71: =IF(D71<>0,1,0) -> 0 | G71: =E71*D71 -> 0
B72: 合計(税込み) | D72: 8％対象 | F72: =SUM(F14:F70) -> 0 | G72: =SUM(G14:G70) -> 0
D73: 10％対象 | G73: =G71 -> 0
B74: * 印は軽減税率8％対象商品となります。

Sheet 広瀬立町
G1: №
B2: 納 品 書 | C2: ='入力 発注書'!D8 -> 46231
D4: 仙台市太白区秋保湯元字寺田原45-11
D5: 有 限 会 社 マ ル カ
E6: TEL 022-398-2408
E7: FAX 022-397-2817
B8: ファミリーマート | C8: 広瀬立町店 様
B9: 下記のとおり納品いたしました
B11: 税込合計金額 ( 原価合計） | C11: =G72+G73 -> 0 | F11: （消費税額等）
B12: 品 名 | C12: 単 価 | E12: 数 量 | F12: 金 額
C13: 売価 | D13: 原価 | F13: 売価 | G13: 原価
A14: ='入力 発注書'!A13 -> 1 | B14: ='入力 発注書'!B13 -> バナナ | C14: ='入力 発注書'!D13 -> 218 | D14: ='入力 発注書'!E13 -> 164 | E14: ='入力 発注書'!M13 -> 0 | F14: =$E14*C14 -> 0 | G14: =$E14*D14 -> 0
A15: ='入力 発注書'!A14 -> 2 | B15: ='入力 発注書'!B14 -> バナナ | C15: ='入力 発注書'!D14 -> 93 | D15: ='入力 発注書'!E14 -> 70 | E15: ='入力 発注書'!M14 -> 0 | F15: =$E15*C15 -> 0 | G15: =E15*D15 -> 0
A16: ='入力 発注書'!A15 -> 3 | B16: ='入力 発注書'!B15 -> 玉ねぎS | C16: ='入力 発注書'!D15 -> 138 | D16: ='入力 発注書'!E15 -> 104 | E16: ='入力 発注書'!M15 -> 0 | F16: =$E16*C16 -> 0 | G16: =E16*D16 -> 0
A17: ='入力 発注書'!A16 -> 4 | B17: ='入力 発注書'!B16 -> 里芋 | C17: ='入力 発注書'!D16 -> 198 | D17: ='入力 発注書'!E16 -> 149 | E17: ='入力 発注書'!M16 -> 0 | F17: =$E17*C17 -> 0 | G17: =E17*D17 -> 0
A18: ='入力 発注書'!A17 -> 5 | B18: ='入力 発注書'!B17 -> 人参 | C18: ='入力 発注書'!D17 -> 128 | D18: ='入力 発注書'!E17 -> 96 | E18: ='入力 発注書'!M17 -> 0 | F18: =$E18*C18 -> 0 | G18: =E18*D18 -> 0
A19: ='入力 発注書'!A18 -> 6 | B19: ='入力 発注書'!B18 -> じゃが芋 | C19: ='入力 発注書'!D18 -> 128 | D19: ='入力 発注書'!E18 -> 96 | E19: ='入力 発注書'!M18 -> 0 | F19: =$E19*C19 -> 0 | G19: =E19*D19 -> 0
A20: ='入力 発注書'!A19 -> 7 | B20: ='入力 発注書'!B19 -> 胡瓜2本 | C20: ='入力 発注書'!D19 -> 138 | D20: ='入力 発注書'!E19 -> 104 | E20: ='入力 発注書'!M19 -> 0 | F20: =$E20*C20 -> 0 | G20: =E20*D20 -> 0
A21: ='入力 発注書'!A20 -> 8 | B21: ='入力 発注書'!B20 -> トマト | C21: ='入力 発注書'!D20 -> 288 | D21: ='入力 発注書'!E20 -> 216 | E21: ='入力 発注書'!M20 -> 0 | F21: =$E21*C21 -> 0 | G21: =E21*D21 -> 0
A22: ='入力 発注書'!A21 -> 9 | B22: ='入力 発注書'!B21 -> フルーツトマト | C22: ='入力 発注書'!D21 -> 238 | D22: ='入力 発注書'!E21 -> 179 | E22: ='入力 発注書'!M21 -> 0 | F22: =$E22*C22 -> 0 | G22: =E22*D22 -> 0
A23: ='入力 発注書'!A22 -> 10 | B23: ='入力 発注書'!B22 -> ミニトマト | C23: ='入力 発注書'!D22 -> 298 | D23: ='入力 発注書'!E22 -> 224 | E23: ='入力 発注書'!M22 -> 0 | F23: =$E23*C23 -> 0 | G23: =E23*D23 -> 0
A24: ='入力 発注書'!A23 -> 11 | B24: ='入力 発注書'!B23 -> ネギ1束 | C24: ='入力 発注書'!D23 -> 198 | D24: ='入力 発注書'!E23 -> 149 | E24: ='入力 発注書'!M23 -> 0 | F24: =$E24*C24 -> 0 | G24: =E24*D24 -> 0
A25: ='入力 発注書'!A24 -> 12 | B25: ='入力 発注書'!B24 -> ピーマン | C25: ='入力 発注書'!D24 -> 198 | D25: ='入力 発注書'!E24 -> 149 | E25: ='入力 発注書'!M24 -> 0 | F25: =$E25*C25 -> 0 | G25: =E25*D25 -> 0
A26: ='入力 発注書'!A25 -> 13 | B26: ='入力 発注書'!B25 -> キャベツ1個 | C26: ='入力 発注書'!D25 -> 248 | D26: ='入力 発注書'!E25 -> 186 | E26: ='入力 発注書'!M25 -> 0 | F26: =$E26*C26 -> 0 | G26: =E26*D26 -> 0
... A70: ='入力 発注書'!A69 -> 57 | B70: ='入力 発注書'!B69 -> 切り干し大根 | C70: ='入力 発注書'!D69 -> 238 | D70: ='入力 発注書'!E69 -> 179 | E70: ='入力 発注書'!M69 -> 0 | F70: =$E70*C70 -> 0 | G70: =E70*D70 -> 0
A71: ='入力 発注書'!A70 -> 58 | B71: ='入力 発注書'!B70 -> 送料 | D71: ='入力 発注書'!M70 -> 0 | E71: =IF(D71<>0,1,0) -> 0 | G71: =E71*D71 -> 0
B72: 合計(税込み) | D72: 8％対象 | F72: =SUM(F14:F70) -> 0 | G72: =SUM(G14:G70) -> 0
D73: 10％対象 | G73: =G71 -> 0
B74: * 印は軽減税率8％対象商品となります。

Sheet A
G1: №
B2: 納 品 書 | C2: ='入力 発注書'!D8 -> 46231
D4: 仙台市太白区秋保湯元字寺田原45-11
D5: 有 限 会 社 マ ル カ
E6: TEL 022-398-2408
E7: FAX 022-397-2817
B8: ファミリーマート | C8: A店 様
B9: 下記のとおり納品いたしました
B11: 税込合計金額 ( 原価合計） | C11: =G72+G73 -> 0 | F11: （消費税額等）
B12: 品 名 | C12: 単 価 | E12: 数 量 | F12: 金 額
C13: 売価 | D13: 原価 | F13: 売価 | G13: 原価
A14: ='入力 発注書'!A13 -> 1 | B14: ='入力 発注書'!B13 -> バナナ | C14: ='入力 発注書'!D13 -> 218 | D14: ='入力 発注書'!E13 -> 164 | E14: ='入力 発注書'!N13 -> 0 | F14: =$E14*C14 -> 0 | G14: =$E14*D14 -> 0
A15: ='入力 発注書'!A14 -> 2 | B15: ='入力 発注書'!B14 -> バナナ | C15: ='入力 発注書'!D14 -> 93 | D15: ='入力 発注書'!E14 -> 70 | E15: ='入力 発注書'!N14 -> 0 | F15: =$E15*C15 -> 0 | G15: =E15*D15 -> 0
A16: ='入力 発注書'!A15 -> 3 | B16: ='入力 発注書'!B15 -> 玉ねぎS | C16: ='入力 発注書'!D15 -> 138 | D16: ='入力 発注書'!E15 -> 104 | E16: ='入力 発注書'!N15 -> 0 | F16: =$E16*C16 -> 0 | G16: =E16*D16 -> 0
A17: ='入力 発注書'!A16 -> 4 | B17: ='入力 発注書'!B16 -> 里芋 | C17: ='入力 発注書'!D16 -> 198 | D17: ='入力 発注書'!E16 -> 149 | E17: ='入力 発注書'!N16 -> 0 | F17: =$E17*C17 -> 0 | G17: =E17*D17 -> 0
A18: ='入力 発注書'!A17 -> 5 | B18: ='入力 発注書'!B17 -> 人参 | C18: ='入力 発注書'!D17 -> 128 | D18: ='入力 発注書'!E17 -> 96 | E18: ='入力 発注書'!N17 -> 0 | F18: =$E18*C18 -> 0 | G18: =E18*D18 -> 0
A19: ='入力 発注書'!A18 -> 6 | B19: ='入力 発注書'!B18 -> じゃが芋 | C19: ='入力 発注書'!D18 -> 128 | D19: ='入力 発注書'!E18 -> 96 | E19: ='入力 発注書'!N18 -> 0 | F19: =$E19*C19 -> 0 | G19: =E19*D19 -> 0
A20: ='入力 発注書'!A19 -> 7 | B20: ='入力 発注書'!B19 -> 胡瓜2本 | C20: ='入力 発注書'!D19 -> 138 | D20: ='入力 発注書'!E19 -> 104 | E20: ='入力 発注書'!N19 -> 0 | F20: =$E20*C20 -> 0 | G20: =E20*D20 -> 0
A21: ='入力 発注書'!A20 -> 8 | B21: ='入力 発注書'!B20 -> トマト | C21: ='入力 発注書'!D20 -> 288 | D21: ='入力 発注書'!E20 -> 216 | E21: ='入力 発注書'!N20 -> 0 | F21: =$E21*C21 -> 0 | G21: =E21*D21 -> 0
A22: ='入力 発注書'!A21 -> 9 | B22: ='入力 発注書'!B21 -> フルーツトマト | C22: ='入力 発注書'!D21 -> 238 | D22: ='入力 発注書'!E21 -> 179 | E22: ='入力 発注書'!N21 -> 0 | F22: =$E22*C22 -> 0 | G22: =E22*D22 -> 0
A23: ='入力 発注書'!A22 -> 10 | B23: ='入力 発注書'!B22 -> ミニトマト | C23: ='入力 発注書'!D22 -> 298 | D23: ='入力 発注書'!E22 -> 224 | E23: ='入力 発注書'!N22 -> 0 | F23: =$E23*C23 -> 0 | G23: =E23*D23 -> 0
A24: ='入力 発注書'!A23 -> 11 | B24: ='入力 発注書'!B23 -> ネギ1束 | C24: ='入力 発注書'!D23 -> 198 | D24: ='入力 発注書'!E23 -> 149 | E24: ='入力 発注書'!N23 -> 0 | F24: =$E24*C24 -> 0 | G24: =E24*D24 -> 0
A25: ='入力 発注書'!A24 -> 12 | B25: ='入力 発注書'!B24 -> ピーマン | C25: ='入力 発注書'!D24 -> 198 | D25: ='入力 発注書'!E24 -> 149 | E25: ='入力 発注書'!N24 -> 0 | F25: =$E25*C25 -> 0 | G25: =E25*D25 -> 0
A26: ='入力 発注書'!A25 -> 13 | B26: ='入力 発注書'!B25 -> キャベツ1個 | C26: ='入力 発注書'!D25 -> 248 | D26: ='入力 発注書'!E25 -> 186 | E26: ='入力 発注書'!N25 -> 0 | F26: =$E26*C26 -> 0 | G26: =E26*D26 -> 0
... A70: ='入力 発注書'!A69 -> 57 | B70: ='入力 発注書'!B69 -> 切り干し大根 | C70: ='入力 発注書'!D69 -> 238 | D70: ='入力 発注書'!E69 -> 179 | E70: ='入力 発注書'!N69 -> 0 | F70: =$E70*C70 -> 0 | G70: =E70*D70 -> 0
A71: ='入力 発注書'!A70 -> 58 | B71: ='入力 発注書'!B70 -> 送料 | D71: ='入力 発注書'!N70 -> 0 | E71: =IF(D71<>0,1,0) -> 0 | G71: =E71*D71 -> 0
B72: 合計(税込み) | D72: 8％対象 | F72: =SUM(F14:F70) -> 0 | G72: =SUM(G14:G70) -> 0
D73: 10％対象 | G73: =G71 -> 0
B74: * 印は軽減税率8％対象商品となります。

Sheet B
G1: №
B2: 納 品 書 | C2: ='入力 発注書'!D8 -> 46231
D4: 仙台市太白区秋保湯元字寺田原45-11
D5: 有 限 会 社 マ ル カ
E6: TEL 022-398-2408
E7: FAX 022-397-2817
B8: ファミリーマート | C8: B店 様
B9: 下記のとおり納品いたしました
B11: 税込合計金額 ( 原価合計） | C11: =G72+G73 -> 0 | F11: （消費税額等）
B12: 品 名 | C12: 単 価 | E12: 数 量 | F12: 金 額
C13: 売価 | D13: 原価 | F13: 売価 | G13: 原価
A14: ='入力 発注書'!A13 -> 1 | B14: ='入力 発注書'!B13 -> バナナ | C14: ='入力 発注書'!D13 -> 218 | D14: ='入力 発注書'!E13 -> 164 | E14: ='入力 発注書'!O13 -> 0 | F14: =$E14*C14 -> 0 | G14: =$E14*D14 -> 0
A15: ='入力 発注書'!A14 -> 2 | B15: ='入力 発注書'!B14 -> バナナ | C15: ='入力 発注書'!D14 -> 93 | D15: ='入力 発注書'!E14 -> 70 | E15: ='入力 発注書'!O14 -> 0 | F15: =$E15*C15 -> 0 | G15: =E15*D15 -> 0
A16: ='入力 発注書'!A15 -> 3 | B16: ='入力 発注書'!B15 -> 玉ねぎS | C16: ='入力 発注書'!D15 -> 138 | D16: ='入力 発注書'!E15 -> 104 | E16: ='入力 発注書'!O15 -> 0 | F16: =$E16*C16 -> 0 | G16: =E16*D16 -> 0
A17: ='入力 発注書'!A16 -> 4 | B17: ='入力 発注書'!B16 -> 里芋 | C17: ='入力 発注書'!D16 -> 198 | D17: ='入力 発注書'!E16 -> 149 | E17: ='入力 発注書'!O16 -> 0 | F17: =$E17*C17 -> 0 | G17: =E17*D17 -> 0
A18: ='入力 発注書'!A17 -> 5 | B18: ='入力 発注書'!B17 -> 人参 | C18: ='入力 発注書'!D17 -> 128 | D18: ='入力 発注書'!E17 -> 96 | E18: ='入力 発注書'!O17 -> 0 | F18: =$E18*C18 -> 0 | G18: =E18*D18 -> 0
A19: ='入力 発注書'!A18 -> 6 | B19: ='入力 発注書'!B18 -> じゃが芋 | C19: ='入力 発注書'!D18 -> 128 | D19: ='入力 発注書'!E18 -> 96 | E19: ='入力 発注書'!O18 -> 0 | F19: =$E19*C19 -> 0 | G19: =E19*D19 -> 0
A20: ='入力 発注書'!A19 -> 7 | B20: ='入力 発注書'!B19 -> 胡瓜2本 | C20: ='入力 発注書'!D19 -> 138 | D20: ='入力 発注書'!E19 -> 104 | E20: ='入力 発注書'!O19 -> 0 | F20: =$E20*C20 -> 0 | G20: =E20*D20 -> 0
A21: ='入力 発注書'!A20 -> 8 | B21: ='入力 発注書'!B20 -> トマト | C21: ='入力 発注書'!D20 -> 288 | D21: ='入力 発注書'!E20 -> 216 | E21: ='入力 発注書'!O20 -> 0 | F21: =$E21*C21 -> 0 | G21: =E21*D21 -> 0
A22: ='入力 発注書'!A21 -> 9 | B22: ='入力 発注書'!B21 -> フルーツトマト | C22: ='入力 発注書'!D21 -> 238 | D22: ='入力 発注書'!E21 -> 179 | E22: ='入力 発注書'!O21 -> 0 | F22: =$E22*C22 -> 0 | G22: =E22*D22 -> 0
A23: ='入力 発注書'!A22 -> 10 | B23: ='入力 発注書'!B22 -> ミニトマト | C23: ='入力 発注書'!D22 -> 298 | D23: ='入力 発注書'!E22 -> 224 | E23: ='入力 発注書'!O22 -> 0 | F23: =$E23*C23 -> 0 | G23: =E23*D23 -> 0
A24: ='入力 発注書'!A23 -> 11 | B24: ='入力 発注書'!B23 -> ネギ1束 | C24: ='入力 発注書'!D23 -> 198 | D24: ='入力 発注書'!E23 -> 149 | E24: ='入力 発注書'!O23 -> 0 | F24: =$E24*C24 -> 0 | G24: =E24*D24 -> 0
A25: ='入力 発注書'!A24 -> 12 | B25: ='入力 発注書'!B24 -> ピーマン | C25: ='入力 発注書'!D24 -> 198 | D25: ='入力 発注書'!E24 -> 149 | E25: ='入力 発注書'!O24 -> 0 | F25: =$E25*C25 -> 0 | G25: =E25*D25 -> 0
A26: ='入力 発注書'!A25 -> 13 | B26: ='入力 発注書'!B25 -> キャベツ1個 | C26: ='入力 発注書'!D25 -> 248 | D26: ='入力 発注書'!E25 -> 186 | E26: ='入力 発注書'!O25 -> 0 | F26: =$E26*C26 -> 0 | G26: =E26*D26 -> 0
... A70: ='入力 発注書'!A69 -> 57 | B70: ='入力 発注書'!B69 -> 切り干し大根 | C70: ='入力 発注書'!D69 -> 238 | D70: ='入力 発注書'!E69 -> 179 | E70: ='入力 発注書'!O69 -> 0 | F70: =$E70*C70 -> 0 | G70: =E70*D70 -> 0
A71: ='入力 発注書'!A70 -> 58 | B71: ='入力 発注書'!B70 -> 送料 | D71: ='入力 発注書'!O70 -> 0 | E71: =IF(D71<>0,1,0) -> 0 | G71: =E71*D71 -> 0
B72: 合計(税込み) | D72: 8％対象 | F72: =SUM(F14:F70) -> 0 | G72: =SUM(G14:G70) -> 0
D73: 10％対象 | G73: =G71 -> 0
B74: * 印は軽減税率8％対象商品となります。
